Workbook

Sheet GANANCIA
A2: FECHA | B2: CLIENTE | C2: NUMERO CLIENTE | D2: PRODUCTO | E2: TAMAÑO | F2: ESTILO | G2: IMAGEN | H2: TEMÁTICA | I2: PRECIO | J2: COSTE | K2: GANANCIA
A3: 45717 | B3: SANDRA-SINCLAIR | D3: TARTA FRUTA | E3: 20 | F3: ARTESANAL | H3: FRUTA | I3: 35 | J3: 15.59 | K3: =SUM(I3-J3) -> 19.41
A4: 45705 | B4: SUSI | D4: TARTA | E4: 20 | F4: TEMATICA | H4: WEED-BEER | I4: 40 | J4: 14.25 | K4: =SUM(I4-J4) -> 25.75
A5: 45703 | B5: SANDRA DELGADO | D5: TARTA | E5: 20 | F5: TEMATICA | G5: SI | H5: BATMAN | I5: 50 | J5: 30.55 | K5: =SUM(I5-J5) -> 19.45
A6: 45704 | B6: CRISTINA- SUSI | D6: TARTA | E6: 18 | F6: TEMATICA | G6: SI | H6: KITTY | I6: 45 | J6: 29.95 | K6: =SUM(I6-J6) -> 15.05
A7: 45710 | B7: ISA | D7: GALLETA | E7: 20 | F7: CASITA | H7: MAMA | I7: 20 | J7: 9.08 | K7: =SUM(I7-J7) -> 10.92
A8: 45718 | B8: VERONICA | D8: TARTA | E8: 24 | F8: TEMATICA | G8: SI | H8: DAYSI | I8: 65 | J8: 40.23 | K8: =SUM(I8-J8) -> 24.77
A9: 29-2 | B9: SARA - ISA | D9: TARTA | E9: 20 | F9: NUMERO | H9: NUMERO 25 | I9: 45 | J9: 15.27 | K9: =SUM(I9-J9) -> 29.73
A10: 45688 | B10: ERIKA | D10: TARTA | E10: 20 | F10: TEMATICA | H10: POKER | I10: 35 | J10: 30.55 | K10: =SUM(I10-J10) -> 4.45
A11: 45682 | B11: ESTEFANIA | D11: TARTA | E11: 20 | F11: TEMATICA | G11: SI | H11: BARBIE | I11: 45 | J11: 30.55 | K11: =SUM(I11-J11) -> 14.45
A12: 45682 | B12: ESTEFANIA | D12: TARTA | E12: 20 | F12: TEMATICA | G12: SI | H12: BLACK PINK | I12: 45 | J12: 30.55 | K12: =SUM(I12-J12) -> 14.45
A13: 45686 | B13: SANDRA - SINCLAIR | D13: TARTA | E13: 24 | F13: TEMATICA | G13: SI | H13: MASHA | I13: 50 | J13: 40.23 | K13: =SUM(I13-J13) -> 9.77
A14: 45686 | B14: ISA | D14: TARTA | E14: 18 | F14: TEMATICA | H14: CAZA | I14: 40 | J14: 29.95 | K14: =SUM(I14-J14) -> 10.05
A15: 45684 | B15: ESTEFANIA | D15: TARTA | E15: 20 | F15: TEMATICA | G15: SI | H15: BEBE JEFAZO | I15: 50 | J15: 30.55 | K15: =SUM(I15-J15) -> 19.45
A16: 45684 | B16: SUSI | D16: TARTA | E16: 20-15 | F16: TEMATICA | G16: SI | H16: PRINCESAS | I16: 60 | J16: 32.46 | K16: =SUM(I16-J16) -> 27.54
A17: 45719 | B17: ERIKA | D17: TARTA | E17: 20 | F17: TEMATICA | G17: SI | H17: BABY SHARK | I17: 40 | J17: 30.55 | K17: =SUM(I17-J17) -> 9.45
A18: 45684 | B18: SUSI | D18: GALLETA | E18: 35 | F18: TEMATICA | H18: MINIONS | I18: 20 | J18: 9.08 | K18: =SUM(I18-J18) -> 10.92
A19: 45733 | B19: SUSI | D19: TARTA | E19: 20 | F19: TEMATICA | G19: SI | H19: SPIDERMAN | I19: 30 | J19: 30.55 | K19: =SUM(I19-J19) -> -0.55
A20: 45684 | B20: ESTEFANIA | D20: TARTA | E20: 20-15 | F20: TEMATICA | G20: SI | H20: TALKING TOM | I20: 70 | J20: 32.46 | K20: =SUM(I20-J20) -> 37.54
A21: 45738 | B21: ISA | D21: PASTAS DE TE | E21: 450 GR | F21: MASA FINA | I21: 12 | J21: 6.44 | K21: =SUM(I21-J21) -> 5.56
A22: 45740 | B22: ISA | D22: CHEESECAKE DDL | E22: 20 | I22: 22 | K22: =SUM(I22-J22) -> 22
A23: 45734 | B23: BEA - AINARA | D23: TARTA | E23: 20 | F23: TEMATICA | H23: UNICORNIOS | I23: 40 | J23: 30.55 | K23: =SUM(I23-J23) -> 9.45
A24: 45734 | B24: JENNY | D24: TARTA | E24: 20 | F24: TEMATICA | H24: BEBE 1 MES | I24: 40 | J24: 30.55 | K24: =SUM(I24-J24) -> 9.45
A25: 45740 | B25: BEA - AINARA | D25: TARTA | E25: 20 | F25: TEMATICA | H25: UNICORNIOS | I25: 30 | J25: 30.55 | K25: =SUM(I25-J25) -> -0.55
A26: 45722 | B26: ESTEFANIA | D26: COOKIES | E26: 15 | I26: 20 | J26: 7.63 | K26: =SUM(I26-J26) -> 12.37
A27: 45722 | B27: ESTEFANIA | D27: GALLETAS RELLENAS | E27: 36 | I27: 40 | J27: 6.13 | K27: =SUM(I27-J27) -> 33.87
A28: 45731 | B28: NIEVES | D28: PASTAS DE TE | I28: 15 | J28: 6.44 | K28: =SUM(I28-J28) -> 8.56
A29: 45777 | B29: MARTA GLS | D29: TARTA | E29: 20-15 | F29: TEMATICA | G29: SI | H29: LILO Y STICH | I29: 70 | J29: 32.46 | K29: =SUM(I29-J29) -> 37.54
A30: 45777 | B30: MARTA GLS | D30: TARTA | E30: 30 | F30: TEMATICA | G30: SI | H30: LILO Y STICH | I30: 30 | J30: 40.24 | K30: =SUM(I30-J30) -> -10.24
A31: 45722 | B31: SONIA ALCALDESA | D31: TARTA | E31: 20 | F31: ARTESANAL | H31: MACETA | I31: 30 | J31: 15.27 | K31: =SUM(I31-J31) -> 14.73
A32: 45738 | B32: MARISA | D32: TARTA | E32: 16 | F32: TEMATICA | H32: BARTOLITO | I32: 40 | J32: 26.56 | K32: =SUM(I32-J32) -> 13.44
A33: 45732 | B33: BARBARA | D33: TARTA | E33: 20 | F33: ARTESANAL | H33: FUTBOL | I33: 35 | J33: 15.27 | K33: =SUM(I33-J33) -> 19.73
A34: 45777 | B34: CHELO | D34: GALLETAS | E34: 45 | F34: TEMATICA | H34: LILO Y STICH | I34: 40 | J34: 9.08 | K34: =SUM(I34-J34) -> 30.92
A35: 45731 | B35: NIEVES | D35: TARTA | E35: 16 | F35: TEMATICA | G35: SI | H35: COLACAO | I35: 35 | J35: 26.56 | K35: =SUM(I35-J35) -> 8.44
A36: 45787 | B36: ISA | D36: TARTA | E36: 16 | F36: ARTESANAL | G36: SI | H36: BOTELLIN | I36: 25 | J36: 12.46 | K36: =SUM(I36-J36) -> 12.54
A37: 45781 | B37: SUSI | D37: GALLETAS | E37: 25 | F37: TEMATICA | H37: LILO Y STICH | I37: 20 | J37: 9.08 | K37: =SUM(I37-J37) -> 10.92
A38: 45779 | B38: SUSI | D38: TARTA | E38: 20 | F38: ARTESANAL | H38: LILO Y STICH | I38: 30 | J38: 15.27 | K38: =SUM(I38-J38) -> 14.73
A39: 45766 | B39: MARI DM | D39: CHEESECAKE SOLO | E39: 18 | I39: 15 | J39: 12 | K39: =SUM(I39-J39) -> 3
A40: 45766 | B40: MARI DM | D40: CHEESECAKE F.ROJOS | E40: 18 | I40: 15 | J40: 13.19 | K40: =SUM(I40-J40) -> 1.81
A41: 45758 | B41: SANDRA - SINCLAIR | D41: T.COCO Y DDL | E41: 20 | I41: 18 | K41: =SUM(I41-J41) -> 18
...

Sheet Compras

Sheet COSTES TODOS
A2: PRODUCTO | C2: COSTE POR TAMAÑO | H2: PRECIO DE VENTA | M2: GANANCIA
B3: 16 CM | C3: 18 CM | D3: 20 CM | E3: 22 CM | F3: OTRO | G3: 16 CM | H3: 18 CM | I3: 20 CM | J3: 24 cm | K3: OTRO | L3: 16 | M3: 18 | N3: 20 | O3: 24 | P3: OTRO
A4: TARTA TEMATICA PERSONALIZADA GANACHE Y FONDANT | B4: ='TEMATICA GANACHE REDONDA'!I55 -> 24.773308 | C4: ='TEMATICA GANACHE REDONDA'!J55 -> 28.157677 | D4: ='TEMATICA GANACHE REDONDA'!K55 -> 30.548767 | E4: ='TEMATICA GANACHE REDONDA'!L55 -> 37.549319 | G4: 45 | H4: 50 | I4: 55 | J4: 60 | L4: =SUM(G4-B4) -> 20.226692 | M4: =SUM(H4-C4) -> 21.842323 | N4: =SUM(I4-D4) -> 24.451233 | O4: =SUM(J4-E4) -> 22.450681 | P4: =SUM(K4-F4) -> 0
A5: TARTA TEMATICA PERSONALIZADA FONDANT | B5: ='TEMATICA FONDANT REDONDA'!I55 -> 26.923308 | C5: ='TEMATICA FONDANT REDONDA'!J55 -> 31.113927 | D5: ='TEMATICA FONDANT REDONDA'!K55 -> 34.311267 | E5: ='TEMATICA FONDANT REDONDA'!L55 -> 42.118069 | G5: 48 | H5: 55 | I5: 60 | J5: 70 | L5: =SUM(G5-B5) -> 21.076692 | M5: =SUM(H5-C5) -> 23.886073 | N5: =SUM(I5-D5) -> 25.688733 | O5: =SUM(J5-E5) -> 27.881931 | P5: =SUM(K5-F5) -> 0
A6: BASICA NATA Y CHOCOLATE | B6: ='Masas basicas'!C94 -> 12.460308 | C6: ='Masas basicas'!D94 -> 13.776105 | D6: ='Masas basicas'!E94 -> 14.245887 | E6: ='Masas basicas'!F94 -> 16.461264 | G6: 30 | H6: 35 | I6: 40 | J6: 50 | L6: =SUM(G6-B6) -> 17.539692 | M6: =SUM(H6-C6) -> 21.223895 | N6: =SUM(I6-D6) -> 25.754113 | O6: =SUM(J6-E6) -> 33.538736 | P6: =SUM(K6-F6) -> 0
A7: TARTA CHOCOLATE SUAVE | B7: ='Masas basicas'!C95 -> 13.319108 | C7: ='Masas basicas'!D95 -> 14.353232 | D7: ='Masas basicas'!E95 -> 15.269937 | E7: ='Masas basicas'!F95 -> 16.461264 | G7: 30 | H7: 35 | I7: 40 | J7: 50 | L7: =SUM(G7-B7) -> 16.680892 | M7: =SUM(H7-C7) -> 20.646768 | N7: =SUM(I7-D7) -> 24.730063 | O7: =SUM(J7-E7) -> 33.538736 | P7: =SUM(K7-F7) -> 0
A8: TARTA ART. BV/ DDL Y FRUTA | B8: ='Masas basicas'!C99 -> 13.610495 | C8: ='Masas basicas'!D99 -> 14.795424 | D8: ='Masas basicas'!E99 -> 15.585715 | E8: ='Masas basicas'!F99 -> 17.990733 | G8: 30 | H8: 35 | I8: 40 | J8: 50 | L8: =SUM(G8-B8) -> 16.389505 | M8: =SUM(H8-C8) -> 20.204576 | N8: =SUM(I8-D8) -> 24.414285 | O8: =SUM(J8-E8) -> 32.009267 | P8: =SUM(K8-F8) -> 0
A9: TARTA MOUSSE FRUTOS ROJOS | B9: ='Masas basicas'!C100 -> 11.716362 | C9: ='Masas basicas'!D100 -> 12.614992 | D9: ='Masas basicas'!E100 -> 15.129715 | E9: ='Masas basicas'!F100 -> 17.367733 | G9: 30 | H9: 35 | I9: 40 | J9: 50 | L9: =SUM(G9-B9) -> 18.283638 | M9: =SUM(H9-C9) -> 22.385008 | N9: =SUM(I9-D9) -> 24.870285 | O9: =SUM(J9-E9) -> 32.632267 | P9: =SUM(K9-F9) -> 0
A10: TARTA MOUSSE FRUTOS ROJOS CHOCOLATE | B10: ='Masas basicas'!C101 -> 13.761495 | C10: ='Masas basicas'!D101 -> 14.660124 | D10: ='Masas basicas'!E101 -> 15.129715 | E10: ='Masas basicas'!F101 -> 17.367733 | G10: 30 | H10: 35 | I10: 40 | J10: 50 | L10: =SUM(G10-B10) -> 16.238505 | M10: =SUM(H10-C10) -> 20.339876 | N10: =SUM(I10-D10) -> 24.870285 | O10: =SUM(J10-E10) -> 32.632267 | P10: =SUM(K10-F10) -> 0
A11: TARTA DE LIMON | B11: ='Masas basicas'!C98 -> 14.616911 | C11: ='Masas basicas'!D98 -> 15.515541 | D11: ='Masas basicas'!E98 -> 16.656381 | E11: ='Masas basicas'!F98 -> 20.773566 | G11: 30 | H11: 35 | I11: 40 | J11: 50 | L11: =SUM(G11-B11) -> 15.383089 | M11: =SUM(H11-C11) -> 19.484459 | N11: =SUM(I11-D11) -> 23.343619 | O11: =SUM(J11-E11) -> 29.226434 | P11: =SUM(K11-F11) -> 0
A12: TARTA ARTESANAL OREO SUAVE | B12: ='Masas basicas'!C97 -> 13.075295 | C12: ='Masas basicas'!D97 -> 13.969002 | D12: ='Masas basicas'!E97 -> 14.991265 | E12: ='Masas basicas'!F97 -> 17.265596 | G12: 30 | H12: 35 | I12: 40 | J12: 50 | L12: =SUM(G12-B12) -> 16.924705 | M12: =SUM(H12-C12) -> 21.030998 | N12: =SUM(I12-D12) -> 25.008735 | O12: =SUM(J12-E12) -> 32.734404 | P12: =SUM(K12-F12) -> 0
A13: TARTA LOTUS | B13: ='Masas basicas'!C96 -> 12.216495 | C13: ='Masas basicas'!D96 -> 13.391874 | D13: ='Masas basicas'!E96 -> 13.967215 | E13: ='Masas basicas'!F96 -> 16.147733 | G13: 30 | H13: 35 | I13: 40 | J13: 50 | L13: =SUM(G13-B13) -> 17.783505 | M13: =SUM(H13-C13) -> 21.608126 | N13: =SUM(I13-D13) -> 26.032785 | O13: =SUM(J13-E13) -> 33.852267 | P13: =SUM(K13-F13) -> 0
A14: TARTA DE ZANAHORIA | B14: ='CARROT CAKE'!I55 -> 13.201637 | C14: ='CARROT CAKE'!J55 -> 16.245324 | D14: ='CARROT CAKE'!K55 -> 17.083127 | E14: ='CARROT CAKE'!L55 -> 23.467369 | G14: 35 | H14: 40 | I14: 45 | J14: 50 | L14: =SUM(G14-B14) -> 21.798363 | M14: =SUM(H14-C14) -> 23.754676 | N14: =SUM(I14-D14) -> 27.916873 | O14: =SUM(J14-E14) -> 26.532631 | P14: =SUM(K14-F14) -> 0
A15: TARTA KINDER | B15: ='TARTA KINDER'!I54 -> 29.175345 | C15: ='TARTA KINDER'!J54 -> 33.074436 | D15: ='TARTA KINDER'!K54 -> 36.302657 | E15: ='TARTA KINDER'!L54 -> 43.199213 | G15: 35 | H15: 40 | I15: 45 | J15: 50 | L15: =SUM(G15-B15) -> 5.8246549 | M15: =SUM(H15-C15) -> 6.925564 | N15: =SUM(I15-D15) -> 8.6973429 | O15: =SUM(J15-E15) -> 6.8007866 | P15: =SUM(K15-F15) -> 0
A16: TARTA OREO | B16: ='TARTA OREO'!I58 -> 21.906944 | C16: ='TARTA OREO'!J58 -> 24.807049 | D16: ='TARTA OREO'!K58 -> 27.036283 | E16: ='TARTA OREO'!L58 -> 32.985426 | G16: 35 | H16: 40 | I16: 45 | J16: 50 | L16: =SUM(G16-B16) -> 13.093056 | M16: =SUM(H16-C16) -> 15.192951 | N16: =SUM(I16-D16) -> 17.963717 | O16: =SUM(J16-E16) -> 17.014574 | P16: =SUM(K16-F16) -> 0
A17: TARTA SAN MARCOS | B17: ='SAN MARCOS'!I50 -> 12.534375 | C17: ='SAN MARCOS'!J50 -> 15.186171 | D17: ='SAN MARCOS'!K50 -> 19.099677 | E17: ='SAN MARCOS'!L50 -> 26.198321 | G17: 30 | H17: 35 | I17: 40 | J17: 50 | L17: =SUM(G17-B17) -> 17.465625 | M17: =SUM(H17-C17) -> 19.813829 | N17: =SUM(I17-D17) -> 20.900323 | O17: =SUM(J17-E17) -> 23.801679 | P17: =SUM(K17-F17) -> 0
A18: TARTA RED VELVET | G18: 35 | H18: 40 | I18: 45 | J18: 50
A19: TARTA CHAJA | B19: =CHAJA!I50 -> 15.071361 | C19: =CHAJA!J50 -> 16.406958 | D19: =CHAJA!K50 -> 18.478105 | E19: =CHAJA!L50 -> 25.599723 | G19: 35 | H19: 40 | I19: 45 | J19: 55 | L19: =SUM(G19-B19) -> 19.928639 | M19: =SUM(H19-C19) -> 23.593042 | N19: =SUM(I19-D19) -> 26.521895 | O19: =SUM(J19-E19) -> 29.400277 | P19: =SUM(K19-F19) -> 0
A20: TARTA FRESAS CON NATA | B20: ='TARTA FRESAS CON NATA'!I51 -> 12.678995 | C20: ='TARTA FRESAS CON NATA'!J51 -> 13.870124 | D20: ='TARTA FRESAS CON NATA'!K51 -> 15.989405 | E20: ='TARTA FRESAS CON NATA'!L51 -> 18.384089 | G20: 30 | H20: 35 | I20: 40 | J20: 50 | L20: =SUM(G20-B20) -> 17.321005 | M20: =SUM(H20-C20) -> 21.129876 | N20: =SUM(I20-D20) -> 24.010595 | O20: =SUM(J20-E20) -> 31.615911 | P20: =SUM(K20-F20) -> 0
A21: TARTA FULL CHOCOLATE | B21: ='TARTA FULL CHOCOLATE'!I56 -> 20.657677 | C21: ='TARTA FULL CHOCOLATE'!J56 -> 25.605933 | D21: ='TARTA FULL CHOCOLATE'!K56 -> 30.13591 | E21: ='TARTA FULL CHOCOLATE'!L56 -> 33.373615 | G21: 35 | H21: 40 | I21: 45 | J21: 60 | L21: =SUM(G21-B21) -> 14.342323 | M21: =SUM(H21-C21) -> 14.394067 | N21: =SUM(I21-D21) -> 14.86409 | O21: =SUM(J21-E21) -> 26.626385 | P21: =SUM(K21-F21) -> 0
A22: PASTA DE TE MASA FINA - CAJA CHICA- 400 GR - 60 PIEZAS | F22: ='PASTAS DE TE'!G14 -> 8.9473956 | K22: 14 | L22: =SUM(G22-B22) -> 0 | M22: =SUM(H22-C22) -> 0 | N22: =SUM(I22-D22) -> 0 | O22: =SUM(J22-E22) -> 0 | P22: =SUM(K22-F22) -> 5.0526044
A23: PASTAS DE TE MASA FINA - CAJA GRANDE - 900 GR - 100 PIEZAS | F23: ='PASTAS DE TE'!G18 -> 14.631318 | K23: 20 | L23: =SUM(G23-B23) -> 0 | M23: =SUM(H23-C23) -> 0 | N23: =SUM(I23-D23) -> 0 | O23: =SUM(J23-E23) -> 0 | P23: =SUM(K23-F23) -> 5.3686822
A24: PASTAS DE TE ELABORADAS CAJA CHICA 500 GR - 30 | F24: ='PASTAS DE TE'!G34 -> 12.064196 | K24: 20 | L24: =SUM(G24-B24) -> 0 | M24: =SUM(H24-C24) -> 0 | N24: =SUM(I24-D24) -> 0 | O24: =SUM(J24-E24) -> 0 | P24: =SUM(K24-F24) -> 7.9358044
A25: PASTAS DE TE ELABORADAS CAJA GRANDE 1 KILO - 60PIEZAS | F25: ='PASTAS DE TE'!G38 -> 17.232584 | K25: 28 | L25: =SUM(G25-B25) -> 0 | M25: =SUM(H25-C25) -> 0 | N25: =SUM(I25-D25) -> 0 | O25: =SUM(J25-E25) -> 0 | P25: =SUM(K25-F25) -> 10.767416
A26: CAJA MIX PASTAS DE TE 1 KILO - 90 PIEZAS | F26: ='PASTAS DE TE'!J54 -> 17.748118 | K26: 23 | L26: =SUM(G26-B26) -> 0 | M26: =SUM(H26-C26) -> 0 | N26: =SUM(I26-D26) -> 0 | O26: =SUM(J26-E26) -> 0 | P26: =SUM(K26-F26) -> 5.2518822
A27: CAJA MIX PASTAS DE TE 2 KILOS | F27: ='PASTAS DE TE'!J55 -> 23.43204 | K27: 30 | L27: =SUM(G27-B27) -> 0 | M27: =SUM(H27-C27) -> 0 | N27: =SUM(I27-D27) -> 0 | O27: =SUM(J27-E27) -> 0 | P27: =SUM(K27-F27) -> 6.56796
A28: GALLETAS PERSONALIZADAS PACK COLE 35 TODAS IGUALES -GLASE | F28: ='GALLETAS BASE'!G47 -> 9.5364416 | G28: 25 | L28: =SUM(G28-B28) -> 25 | M28: =SUM(H28-C28) -> 0 | N28: =SUM(I28-D28) -> 0 | O28: =SUM(J28-E28) -> 0 | P28: =SUM(K28-F28) -> -9.5364416
A29: GALLETAS PERSONALIZADAS PACK CUMPLEAÑOS -4 DISEÑOS -35 -GLASE | F29: ='GALLETAS BASE'!G47 -> 9.5364416 | G29: 30 | L29: =SUM(G29-B29) -> 30 | M29: =SUM(H29-C29) -> 0 | N29: =SUM(I29-D29) -> 0 | O29: =SUM(J29-E29) -> 0 | P29: =SUM(K29-F29) -> -9.5364416
A30: GALLETAS PERSONALIZADAS PACK TEMATICOS - SET 1 KG 25-30 -GLASE | F30: ='GALLETAS BASE'!G47 -> 9.5364416 | G30: 30 | L30: =SUM(G30-B30) -> 30 | M30: =SUM(H30-C30) -> 0 | N30: =SUM(I30-D30) -> 0 | O30: =SUM(J30-E30) -> 0 | P30: =SUM(K30-F30) -> -9.5364416
A31: GALLETAS PERSONALZIADAS PACK PUZZLE - 30 GALLETAS - IGUALES - GLASE | F31: ='GALLETAS BASE'!G47 -> 9.5364416 | G31: 30 | L31: =SUM(G31-B31) -> 30 | M31: =SUM(H31-C31) -> 0 | N31: =SUM(I31-D31) -> 0 | O31: =SUM(J31-E31) -> 0 | P31: =SUM(K31-F31) -> -9.5364416
A32: GALLETAS RAMO DE FLORES - GLASE - 8 FLORES GRANDES | F32: ='RAMO DE FLORES'!G47 -> 8.3345086 | G32: 20 | L32: =SUM(G32-B32) -> 20 | M32: =SUM(H32-C32) -> 0 | N32: =SUM(I32-D32) -> 0 | O32: =SUM(J32-E32) -> 0 | P32: =SUM(K32-F32) -> -8.3345086
A33: GALLETAS RAMO DE FLORES + MINI CAJITA 10 GALLETAS - GLASE | F33: ='GALLETAS BASE'!G47 -> 9.5364416 | G33: 22 | L33: =SUM(G33-B33) -> 22 | M33: =SUM(H33-C33) -> 0 | N33: =SUM(I33-D33) -> 0 | O33: =SUM(J33-E33) -> 0 | P33: =SUM(K33-F33) -> -9.5364416
A34: GALLETAS EN CASITA + 6 MINI GALLETAS - GLASE | F34: ='GALLETAS BASE'!G47 -> 9.5364416 | G34: 30 | L34: =SUM(G34-B34) -> 30 | M34: =SUM(H34-C34) -> 0 | N34: =SUM(I34-D34) -> 0 | O34: =SUM(J34-E34) -> 0 | P34: =SUM(K34-F34) -> -9.5364416
A35: GALLETAS PERSONALIZADAS FONDANT - 35 IGUAL FORMA | F35: ='GALLETAS BASE'!G28 -> 8.5409416 | G35: 30 | L35: =SUM(G35-B35) -> 30 | M35: =SUM(H35-C35) -> 0 | N35: =SUM(I35-D35) -> 0 | O35: =SUM(J35-E35) -> 0 | P35: =SUM(K35-F35) -> -8.5409416
A36: GALLETAS PERSONALIZADAS FONDANT - SET 25 GRANDES | F36: ='GALLETAS BASE'!G28 -> 8.5409416 | G36: 35 | L36: =SUM(G36-B36) -> 35 | M36: =SUM(H36-C36) -> 0 | N36: =SUM(I36-D36) -> 0 | O36: =SUM(J36-E36) -> 0 | P36: =SUM(K36-F36) -> -8.5409416
A37: GALLETAS CORAZON CRISTAL - PACK COLE 35 UN | G37: 20 | L37: =SUM(G37-B37) -> 20 | M37: =SUM(H37-C37) -> 0 | N37: =SUM(I37-D37) -> 0 | O37: =SUM(J37-E37) -> 0 | P37: =SUM(K37-F37) -> 0
A38: GALLETAS PACK DOBLE COLE - 30 PAQUETES - MERMELADAS Y CRISTAL | G38: 30 | L38: =SUM(G38-B38) -> 30 | M38: =SUM(H38-C38) -> 0 | N38: =SUM(I38-D38) -> 0 | O38: =SUM(J38-E38) -> 0 | P38: =SUM(K38-F38) -> 0
A39: CRUMBLE COOKIES - GRANDES 100GR - 15 UNIDADES | F39: ='CRUMBLE COOKIES'!K11 -> 16.67894 | G39: 20 | K39: 20 | L39: =SUM(G39-B39) -> 20 | M39: =SUM(H39-C39) -> 0 | N39: =SUM(I39-D39) -> 0 | O39: =SUM(J39-E39) -> 0 | P39: =SUM(K39-F39) -> 3.32106
A40: CRUMBLE COOKIES - GRANDES 100GR - 6 UNIDADES | F40: ='CRUMBLE COOKIES'!K12 -> 9.5204733 | G40: 12 | K40: 15 | L40: =SUM(G40-B40) -> 12 | M40: =SUM(H40-C40) -> 0 | N40: =SUM(I40-D40) -> 0 | O40: =SUM(J40-E40) -> 0 | P40: =SUM(K40-F40) -> 5.4795267
A41: COOKIES PACK COLE MINI 50GR, 35 UNIDADES | F41: ='CRUMBLE COOKIES'!K9 -> 16.67894 | G41: 20 | K41: 22 | L41: =SUM(G41-B41) -> 20 | M41: =SUM(H41-C41) -> 0 | N41: =SUM(I41-D41) -> 0 | O41: =SUM(J41-E41) -> 0 | P41: =SUM(K41-F41) -> 5.32106
...

Sheet PASTAS DE TE
E1: Sablee de manga - Pastas de te
A2: SABLEE DE MANGA
A3: INGREDIENTES | B3: CANTIDAD | C3: UNIDADES | D3: PRECIO | E3: COSTO 900 GR | G3: INGREDIENTES | H3: CANTIDAD | I3: UNIDADES | J3: PRECIO | K3: COSTO
G4: CAJA | H4: 1 | I4: 1 | J4: 2.2 | K4: =H4*J4/I4 -> 2.2
A5: Mantequilla | B5: 180 | C5: 250 | D5: 2.56 | E5: =B5*D5/C5 -> 1.8432 | G5: Papel horno | H5: 1 | I5: 20 | J5: 1.13 | K5: =H5*J5/I5 -> 0.0565
A6: Azucar glass | B6: 100 | C6: 1000 | D6: 5 | E6: =B6*D6/C6 -> 0.5 | G6: Gastos herram | H6: 1 | I6: 100 | J6: 10 | K6: =H6*J6/I6 -> 0.1
A7: Huevos | B7: 2 | C7: 12 | D7: 2.5 | E7: =B7*D7/C7 -> 0.41666667 | G7: Horno | H7: 30 | I7: 60 | J7: 1 | K7: =H7*J7/I7 -> 0.5
A8: Harina | B8: 250 | C8: 1000 | D8: 1.46 | E8: =B8*D8/C8 -> 0.365 | G8: Agua | H8: 12 | I8: 1000 | J8: 1.97 | K8: =H8*J8/I8 -> 0.02364
A9: Vainilla | B9: 10 | C9: 200 | D9: 6.9 | E9: =B9*D9/C9 -> 0.345 | G9: Batidora | H9: 5 | I9: 60 | J9: 1 | K9: =H9*J9/I9 -> 0.083333333
A10: Citricos | B10: 10 | C10: 1000 | D10: 1 | E10: =B10*D10/C10 -> 0.01 | G10: MANGAS | H10: 2 | I10: 20 | J10: 3 | K10: =H10*J10/I10 -> 0.3
A11: Chocolate blanco | B11: 30 | C11: 100 | D11: 1.15 | E11: =B11*D11/C11 -> 0.345 | K11: =SUM(K4:K10) -> 3.2634733
A12: Chocolate NEGRO | B12: 30 | C12: 1000 | D12: 1.15 | E12: =B12*D12/C12 -> 0.0345 | G12: MASAS FINAS
A13: Pistachos | C13: 1000 | D13: 19.95 | E13: =B13*D13/C13 -> 0 | G13: COSTES 450KG | H13: PVP 450 | I13: profit
A14: Nueces | C14: 1000 | D14: 15.89 | E14: =B14*D14/C14 -> 0 | G14: =E19+K11 -> 8.9473956 | H14: 14 | I14: =H14-G14 -> 5.0526044
A15: Almendras | C15: 1000 | D15: 17.25 | E15: =B15*D15/C15 -> 0
A16: mix frutos secos | B16: 20 | C16: 40 | D16: 0.85 | E16: =B16*D16/C16 -> 0.425
A17: caja | B17: 1 | C17: 1 | D17: 1.2 | E17: =B17*D17/C17 -> 1.2 | G17: COSTES 900 KG | H17: PVP 900
A18: cacao | B18: 20 | C18: 450 | D18: 4.49 | E18: =B18*D18/C18 -> 0.19955556 | G18: =(E19*2)+K11 -> 14.631318 | H18: 20 | I18: =H18-G18 -> 5.3686822
E19: =SUM(E5+E6+E7+E8+E9+E10+E11+E12+E13+E14+E15+E16+E17+E18) -> 5.6839222
A21: De esta masa sale 400gr de masitas | F21: MITAD DE CHOCOLATE Y MITAD DE VAINILLA O CITRICO
A22: En una caja de 400gr entran 60-70 unidades | F22: DECOS EN CHOCOLATE ,FRUTOS SECOS, FRUTA ABRILLANTADA
A25: SABLEE DURA - PASTAS RELLENAS
A26: INGREDIENTES | B26: CANTIDAD | C26: UNIDADES | D26: PRECIO | E26: COSTO
A28: Mantequilla | B28: 150 | C28: 250 | D28: 2.56 | E28: =B28*D28/C28 -> 1.536
A29: Azucar glass | B29: 100 | C29: 1000 | D29: 5 | E29: =B29*D29/C29 -> 0.5
A30: Huevos | B30: 1 | C30: 12 | D30: 2.5 | E30: =B30*D30/C30 -> 0.20833333
A31: Harina | B31: 250 | C31: 1000 | D31: 1.46 | E31: =B31*D31/C31 -> 0.365
A32: Vainilla | B32: 10 | C32: 200 | D32: 6.9 | E32: =B32*D32/C32 -> 0.345 | G32: PASTAS DE TE RELLENAS
A33: Citricos | B33: 10 | C33: 1000 | D33: 1 | E33: =B33*D33/C33 -> 0.01 | G33: COSTES 500 KG | H33: PVP 450 | I33: profit | J33: hs pagadas
A34: Chocolate blanco | B34: 30 | C34: 100 | D34: 1.15 | E34: =B34*D34/C34 -> 0.345 | G34: =SUM(E42+E51+K50) -> 12.064196 | H34: 20 | I34: =SUM(H34-G34) -> 7.9358044 | J34: =K30
A35: Chocolate NEGRO | B35: 30 | C35: 1000 | D35: 1.15 | E35: =B35*D35/C35 -> 0.0345
A36: Pistachos | C36: 1000 | D36: 19.95 | E36: =B36*D36/C36 -> 0
A37: Nueces | C37: 1000 | D37: 15.89 | E37: =B37*D37/C37 -> 0 | G37: COSTES 1 KG | H37: PVP 900
A38: Almendras | C38: 1000 | D38: 17.25 | E38: =B38*D38/C38 -> 0 | G38: =(E42*2)+E51+K50 -> 17.232584 | H38: 28 | I38: =H38-G38 -> 10.767416 | J38: =K30
A39: mix frutos secos | B39: 20 | C39: 40 | D39: 0.85 | E39: =B39*D39/C39 -> 0.425
A40: caja | B40: 1 | C40: 1 | D40: 1.2 | E40: =B40*D40/C40 -> 1.2
A41: cacao | B41: 20 | C41: 450 | D41: 4.49 | E41: =B41*D41/C41 -> 0.19955556
E42: =SUM(E28+E29+E30+E31+E32+E33+E34+E35+E36+E37+E38+E39+E40+E41) -> 5.1683889 | G42: INGREDIENTES | H42: CANTIDAD | I42: UNIDADES | J42: PRECIO | K42: COSTO
G43: CAJA | H43: 1 | I43: 1 | J43: 2.2 | K43: =H43*J43/I43 -> 2.2
B44: RELLENOS | G44: Papel horno | H44: 1 | I44: 20 | J44: 1.13 | K44: =H44*J44/I44 -> 0.0565
...

Sheet PASTA FROLLA
A2: MASA FROLLA
A3: INGREDIENTES | B3: 20 CM | C3: 22 CM | D3: UNIDADES PAQ | E3: PRECIO | F3: COSTO 8-10 p | G3: COSTO 12-15
A4: MANTECA | B4: 200 | C4: 300 | D4: 250 | E4: 2.56 | F4: =(B4*E4)/D4 -> 2.048 | G4: =C5*E5/D5 -> 0.33525
A5: AZUCAR BLANCA | B5: 150 | C5: 225 | D5: 1000 | E5: 1.49 | F5: =(B5*E5)/D5 -> 0.2235 | G5: =C6*E6/D6 -> 0.625
A6: HUEVOS | B6: 2 | C6: 3 | D6: 12 | E6: 2.5 | F6: =(B6*E6)/D6 -> 0.41666667 | G6: =C7*E7/D7 -> 0.149
A7: LIMON RALLADURA | B7: 1 | C7: 1 | D7: 10 | E7: 1.49 | F7: =(B7*E7)/D7 -> 0.149 | G7: =C8*E8/D8 -> 0.14618644
A8: VAINILLA | B8: 5 | C8: 5 | D8: 236 | E8: 6.9 | F8: =(B8*E8)/D8 -> 0.14618644 | G8: =C8*E8/D8 -> 0.14618644
A9: HARINA | B9: 300 | C9: 500 | D9: 1000 | E9: 1.49 | F9: =SUM(F5:F8) -> 0.93535311 | G9: =SUM(G5:G8) -> 1.0663729
A10: MAICENA | B10: 100 | C10: 100 | D10: 400 | E10: 4 | F10: =SUM(F6:F9) -> 1.6472062 | G10: =SUM(G6:G9) -> 1.5077458
A11: SAL | B11: 3 | C11: 3 | D11: 1000 | E11: 1 | F11: =SUM(F7:F10) -> 2.8777458 | G11: =SUM(G7:G10) -> 2.8664915
F12: =SUM(F4:F11) -> 8.4436582 | G12: =SUM(G4:G11) -> 6.8422331
A13: RELLENO
A14: INGREDIENTES | B14: 20 CM | C14: 22 CM | D14: UNIDADES PAQ | E14: PRECIO | F14: COSTO 8-10 p | G14: COSTO 12-15
A15: MEMBRILLO | B15: 350 | C15: 450 | D15: 350 | E15: 1.29 | F15: =(B15*E15)/D15 -> 1.29 | G15: =(C15*E15/D15) -> 1.6585714
F16: =F15 -> 1.29 | G16: =G15 -> 1.6585714
A18: GASTOS INDIRECTOS
A19: PRODUCTO | B19: 20 CM | C19: 22 CM | D19: UNIDADES | E19: PRECIO | F19: COSTO 20CM | G19: COSTO 22CM
A20: BATIDORA | B20: 10 | C20: 10 | D20: 60 | E20: 1 | F20: =(B20*E20/D20) -> 0.16666667 | G20: =(C20*E20/D20) -> 0.16666667
A21: PAPEL HORNO | B21: 2 | C21: 2 | D21: 20 | E21: 1.13 | F21: =(B21*E21/D21) -> 0.113 | G21: =(C21*E21/D21) -> 0.113
A22: NEVERA | B22: 30 | C22: 30 | D22: 60 | E22: 1 | F22: =(B22*E22/D22) -> 0.5 | G22: =(C22*E22/D22) -> 0.5
A23: HORNO | B23: 30 | C23: 30 | D23: 60 | E23: 1 | F23: =(B23*E23/D23) -> 0.5 | G23: =(C23*E23/D23) -> 0.5
A24: PLATO 25 CM | B24: 1 | C24: 1 | D24: 1 | E24: 1 | F24: =(B24*E24/D24) -> 1 | G24: =(C24*E24/D24) -> 1
A25: CAJA 25 | B25: 1 | C25: 1 | D25: 1 | E25: 2.2 | F25: =(B25*E25/D25) -> 2.2 | G25: =(C25*E25/D25) -> 2.2
F26: =SUM(F20:F25) -> 4.4796667 | G26: =SUM(G20:G25) -> 4.4796667
D28: COSTE TOTAL | F28: =SUM(F12+F16+F26) -> 14.213325 | G28: =SUM(G12+G16+G26) -> 12.980471
D29: PRECIO VENTA | F29: 20 | G29: 22
D30: GANANCIA | F30: =SUM(F29-F28) -> 5.7866751 | G30: =SUM(G29-G28) -> 9.0195289

Sheet RAMO DE FLORES
C2: MASA BASE DE GALLETAS
A3: INGREDIENTES | B3: CANTIDAD | C3: UNIDADES | D3: PRECIO | E3: COSTO
G4: DE ESTA MASA SALEN 7 FLORES Y 1 HOJA
A5: Mantequilla | B5: 100 | C5: 1000 | D5: 2.56 | E5: =B5*D5/C5 -> 0.256
A6: Azucar glass | B6: 100 | C6: 1000 | D6: 5 | E6: =B6*D6/C6 -> 0.5
A7: Huevos | B7: 1 | C7: 12 | D7: 2.5 | E7: =B7*D7/C7 -> 0.20833333
A8: Harina | B8: 200 | C8: 1000 | D8: 1.46 | E8: =B8*D8/C8 -> 0.292
A9: Vainilla | B9: 5 | C9: 200 | D9: 6.9 | E9: =B9*D9/C9 -> 0.1725
A10: Citricos | B10: 5 | C10: 1000 | D10: 1 | E10: =B10*D10/C10 -> 0.005
A11: Cacao | B11: 0 | C11: 450 | D11: 4.99 | E11: =B11*D11/C11 -> 0
E12: =SUM(E5:E11) -> 1.4338333
B13: =SUM(B5:B11) -> 411
B15: GLASE REAL
A16: INGREDIENTES | B16: CANTIDAD | C16: UNIDADES | D16: PRECIO | E16: COSTO | H16: GASTOS INDIRECTOS
G17: INGREDIENTES | H17: CANTIDAD | I17: UNIDADES | J17: PRECIO | K17: COSTO
A18: PALITOS | B18: 8 | C18: 1000 | D18: 2.56 | E18: =B18*D18/C18 -> 0.02048
A19: PAPEL ENVOLTORIO | B19: 1 | C19: 1000 | D19: 5 | E19: =B19*D19/C19 -> 0.005 | G19: Papel horno | H19: 1 | I19: 20 | J19: 1.13 | K19: =H19*J19/I19 -> 0.0565
A20: BOLSITAS | B20: 8 | C20: 12 | D20: 2.5 | E20: =B20*D20/C20 -> 1.6666667 | G20: Gastos herram | H20: 1 | I20: 100 | J20: 10 | K20: =H20*J20/I20 -> 0.1
A21: CUERDA | B21: 1 | C21: 1000 | D21: 1.46 | E21: =B21*D21/C21 -> 0.00146 | G21: Horno | H21: 30 | I21: 60 | J21: 1 | K21: =H21*J21/I21 -> 0.5
A22: ETIQUETA | B22: 2 | C22: 200 | D22: 6.9 | E22: =B22*D22/C22 -> 0.069 | G22: Agua | H22: 12 | I22: 1000 | J22: 1.97 | K22: =H22*J22/I22 -> 0.02364
A23: Glase | B23: 450 | C23: 900 | D23: 6.34 | E23: =B23*D23/C23 -> 3.17 | G23: Batidora | H23: 5 | I23: 60 | J23: 1 | K23: =H23*J23/I23 -> 0.083333333
A24: Colorantes | B24: 4 | C24: 28 | D24: 2.6 | E24: =B24*D24/C24 -> 0.37142857
A25: POLVOS | B25: 4 | C25: 1000 | D25: 1 | E25: =B25*D25/C25 -> 0.004 | K25: =SUM(K19:K24) -> 0.76347333
A26: CAJA | B26: 1 | C26: 1 | D26: 1.75 | E26: 2.2
B27: 0 | C27: 100 | D27: 11 | E27: =B27*D27/C27 -> 0 | G27: COSTES 1KG | H27: PVP 20-25
B28: 0 | C28: 450 | D28: 4.99 | E28: =B28*D28/C28 -> 0 | G28: =SUM(#REF!+K25) -> #REF! | H28: 25
E29: =SUM(E18:E28) -> 7.5080352
G31: COSTES 2 KG | H31: PVP 40-50
G32: =(#REF!*2)+K25 -> #REF! | H32: 40
H35: GASTOS INDIRECTOS
G36: INGREDIENTES | H36: CANTIDAD | I36: UNIDADES | J36: PRECIO | K36: COSTO
G38: Papel horno | H38: 1 | I38: 20 | J38: 1.13 | K38: =H38*J38/I38 -> 0.0565
G39: Mangas | H39: 10 | I39: 100 | J39: 1.63 | K39: =H39*J39/I39 -> 0.163
G40: Horno | H40: 30 | I40: 60 | J40: 1 | K40: =H40*J40/I40 -> 0.5
G41: Agua | H41: 12 | I41: 1000 | J41: 1.97 | K41: =H41*J41/I41 -> 0.02364
G42: Batidora | H42: 5 | I42: 60 | J42: 1 | K42: =H42*J42/I42 -> 0.083333333
K44: =SUM(K38:K43) -> 0.82647333
G46: COSTES 1KG | H46: PVP 20-25 | I46: profit | J46: hs pagadas
G47: =SUM(E29+K44) -> 8.3345086 | H47: 30 | I47: =H47-G47 -> 21.665491 | J47: =K43
G50: COSTES 2 KG | H50: PVP 40-50
...

Sheet GALLETAS BASE
C2: MASA BASE DE GALLETAS
A3: INGREDIENTES | B3: CANTIDAD | C3: UNIDADES | D3: PRECIO | E3: COSTO
G4: de esta masa base sale un kilo de galletas
A5: Mantequilla | B5: 200 | C5: 1000 | D5: 2.56 | E5: =B5*D5/C5 -> 0.512 | G5: dependiendo del tamaño del cortador
A6: Azucar glass | B6: 200 | C6: 1000 | D6: 5 | E6: =B6*D6/C6 -> 1 | G6: en circular pequeño 50
A7: Huevos | B7: 1 | C7: 12 | D7: 2.5 | E7: =B7*D7/C7 -> 0.20833333 | G7: halloween 30
A8: Harina | B8: 500 | C8: 1000 | D8: 1.46 | E8: =B8*D8/C8 -> 0.73
A9: Vainilla | B9: 10 | C9: 200 | D9: 6.9 | E9: =B9*D9/C9 -> 0.345
A10: Citricos | B10: 10 | C10: 1000 | D10: 1 | E10: =B10*D10/C10 -> 0.01
A11: Cacao | B11: 20 | C11: 450 | D11: 4.99 | E11: =B11*D11/C11 -> 0.22177778
E12: =SUM(E5:E11) -> 3.0271111
B13: =SUM(B5:B11) -> 941
B16: FONDANT | H16: GASTOS INDIRECTOS
A17: INGREDIENTES | B17: CANTIDAD | C17: UNIDADES | D17: PRECIO | E17: COSTO | G17: INGREDIENTES | H17: CANTIDAD | I17: UNIDADES | J17: PRECIO | K17: COSTO
A19: Mantequilla | B19: 200 | C19: 1000 | D19: 2.56 | E19: =B19*D19/C19 -> 0.512 | G19: Papel horno | H19: 1 | I19: 20 | J19: 1.13 | K19: =H19*J19/I19 -> 0.0565
A20: Azucar glass | B20: 200 | C20: 1000 | D20: 5 | E20: =B20*D20/C20 -> 1 | G20: Gastos herram | H20: 1 | I20: 100 | J20: 10 | K20: =H20*J20/I20 -> 0.1
A21: Huevos | B21: 1 | C21: 12 | D21: 2.5 | E21: =B21*D21/C21 -> 0.20833333 | G21: Horno | H21: 30 | I21: 60 | J21: 1 | K21: =H21*J21/I21 -> 0.5
A22: Harina | B22: 500 | C22: 1000 | D22: 1.46 | E22: =B22*D22/C22 -> 0.73 | G22: Agua | H22: 12 | I22: 1000 | J22: 1.97 | K22: =H22*J22/I22 -> 0.02364
A23: Vainilla | B23: 10 | C23: 200 | D23: 6.9 | E23: =B23*D23/C23 -> 0.345 | G23: Batidora | H23: 5 | I23: 60 | J23: 1 | K23: =H23*J23/I23 -> 0.083333333
A24: Fondant | B24: 500 | C24: 2000 | D24: 10.75 | E24: =B24*D24/C24 -> 2.6875
A25: Colorantes | B25: 1 | C25: 28 | D25: 2.6 | E25: =B25*D25/C25 -> 0.092857143 | K25: =SUM(K19:K24) -> 0.76347333
A26: Citricos | B26: 10 | C26: 1000 | D26: 1 | E26: =B26*D26/C26 -> 0.01
A27: Caja 26x26x10 dcora | B27: 1 | C27: 1 | D27: 1.75 | E27: =B27*D27/C27 -> 1.75 | G27: COSTES 1KG | H27: PVP 20-25
A28: Blonda | B28: 2 | C28: 100 | D28: 11 | E28: =B28*D28/C28 -> 0.22 | G28: =SUM(E30+K25) -> 8.5409416 | H28: 25
A29: Cacao | B29: 20 | C29: 450 | D29: 4.99 | E29: =B29*D29/C29 -> 0.22177778
E30: =SUM(E19:E29) -> 7.7774683
G31: COSTES 2 KG | H31: PVP 40-50
G32: =(E30*2)+K25 -> 16.31841 | H32: 40
B35: GLASE REAL | H35: GASTOS INDIRECTOS
A36: INGREDIENTES | B36: CANTIDAD | C36: UNIDADES | D36: PRECIO | E36: COSTO | G36: INGREDIENTES | H36: CANTIDAD | I36: UNIDADES | J36: PRECIO | K36: COSTO
A38: Mantequilla | B38: 200 | C38: 1000 | D38: 2.56 | E38: =B38*D38/C38 -> 0.512 | G38: Papel horno | H38: 1 | I38: 20 | J38: 1.13 | K38: =H38*J38/I38 -> 0.0565
A39: Azucar glass | B39: 200 | C39: 1000 | D39: 5 | E39: =B39*D39/C39 -> 1 | G39: Mangas | H39: 10 | I39: 100 | J39: 1.63 | K39: =H39*J39/I39 -> 0.163
A40: Huevos | B40: 1 | C40: 12 | D40: 2.5 | E40: =B40*D40/C40 -> 0.20833333 | G40: Horno | H40: 30 | I40: 60 | J40: 1 | K40: =H40*J40/I40 -> 0.5
A41: Harina | B41: 500 | C41: 1000 | D41: 1.46 | E41: =B41*D41/C41 -> 0.73 | G41: Agua | H41: 12 | I41: 1000 | J41: 1.97 | K41: =H41*J41/I41 -> 0.02364
A42: Vainilla | B42: 10 | C42: 200 | D42: 6.9 | E42: =B42*D42/C42 -> 0.345 | G42: Batidora | H42: 5 | I42: 60 | J42: 1 | K42: =H42*J42/I42 -> 0.083333333
A43: Glase | B43: 450 | C43: 900 | D43: 6.34 | E43: =B43*D43/C43 -> 3.17
A44: Colorantes | B44: 1 | C44: 28 | D44: 2.6 | E44: =B44*D44/C44 -> 0.092857143 | K44: =SUM(K38:K43) -> 0.82647333
A45: Citricos | B45: 10 | C45: 1000 | D45: 1 | E45: =B45*D45/C45 -> 0.01
A46: Caja 26x26x10 dcora | B46: 1 | C46: 1 | D46: 1.75 | E46: 2.2 | G46: COSTES 1KG | H46: PVP 20-25 | I46: profit | J46: hs pagadas
A47: Blonda | B47: 2 | C47: 100 | D47: 11 | E47: =B47*D47/C47 -> 0.22 | G47: =SUM(E49+K44) -> 9.5364416 | H47: 30 | I47: =H47-G47 -> 20.463558 | J47: =K43
...

Sheet SAN MARCOS
B3: INGREDIENTES | C3: CANT 8-10 p | D3: CANT 12-15 | E3: CANT 18-20 p | F3: CANT 25-28 | G3: UNIDADES PAQ | H3: PRECIO | I3: COSTO 8-10 p | J3: COSTO 12-15 | K3: COSTO 18-20 p | L3: COSTO 25-28
A5: BIZCOCHO | B5: Harina | C5: 150 | D5: 180 | E5: 240 | F5: 270 | G5: 1000 | H5: 1.07 | I5: =(C5*H5)/G5 -> 0.1605 | J5: =D6*H6/G6 -> 1.25 | K5: =(E5*H5)/G5 -> 0.2568 | L5: =(F5*H5)/G5 -> 0.2889
A6: VAINILLA | B6: Huevos | C6: 5 | D6: 6 | E6: 8 | F6: 9 | G6: 12 | H6: 2.5 | I6: =(C6*H6)/G6 -> 1.0416667 | J6: =D7*H7/G7 -> 0.2682 | K6: =(E6*H6)/G6 -> 1.6666667 | L6: =(F6*H6)/G6 -> 1.875
B7: Azucar | C7: 150 | D7: 180 | E7: 240 | F7: 270 | G7: 1000 | H7: 1.49 | I7: =(C7*H7)/G7 -> 0.2235 | J7: =D8*H8/G8 -> 0.29237288 | K7: =(E7*H7)/G7 -> 0.3576 | L7: =(F7*H7)/G7 -> 0.4023
B8: Vainilla | C8: 5 | D8: 10 | E8: 10 | F8: 15 | G8: 236 | H8: 6.9 | I8: =(C8*H8)/G8 -> 0.14618644 | J8: =D8*H8/G8 -> 0.29237288 | K8: =(E8*H8)/G8 -> 0.29237288 | L8: =(F8*H8)/G8 -> 0.43855932
I9: =SUM(I5:I8) -> 1.5718531 | J9: =SUM(J5:J8) -> 2.1029458 | K9: =SUM(K5:K8) -> 2.5734395 | L9: =SUM(L5:L8) -> 3.0047593
B11: Azucar | C11: 100 | D11: 120 | E11: 150 | F11: 200 | G11: 1000 | H11: 1.49 | I11: =(C11*H11)/G11 -> 0.149 | J11: =D11*H11/G11 -> 0.1788 | K11: =(E11*H11)/G11 -> 0.2235 | L11: =(F11*H11)/G11 -> 0.298
A12: ALMIBAR | B12: Agua | C12: 100 | D12: 120 | E12: 150 | F12: 200 | G12: 1000 | H12: 0.25 | I12: =(C12*H12)/G12 -> 0.025 | J12: =D12*H12/G12 -> 0.03 | K12: =(E12*H12)/G12 -> 0.0375 | L12: =(F12*H12)/G12 -> 0.05
B13: Vainilla | C13: 3 | D13: 4 | E13: 5 | F13: 9 | G13: 236 | H13: 6.9 | I13: =(C13*H13)/G13 -> 0.087711864 | J13: =D13*H13/G13 -> 0.11694915 | K13: =(E13*H13)/G13 -> 0.14618644 | L13: =(F13*H13)/G13 -> 0.26313559
I14: =SUM(I11:I13) -> 0.26171186 | J14: =SUM(J11:J13) -> 0.32574915 | K14: =SUM(K11:K13) -> 0.40718644 | L14: =SUM(L11:L13) -> 0.61113559
A16: RELLENO | B16: CHOCOLATE | C16: 100 | D16: 200 | E16: 300 | F16: 400 | G16: 100 | H16: 1.27 | I16: =(C16*H16)/G16 -> 1.27 | J16: =D16*H16/G16 -> 2.54 | K16: =(E16*H16)/G16 -> 3.81 | L16: =(F16*H16)/G16 -> 5.08
A17: TRUFA Y | B17: Nata | C17: 100 | D17: 200 | E17: 300 | F17: 400 | G17: 600 | H17: 2.36 | I17: =(C17*H17)/G17 -> 0.39333333 | J17: =D17*H17/G17 -> 0.78666667 | K17: =(E17*H17)/G17 -> 1.18 | L17: =(F17*H17)/G17 -> 1.5733333
A18: NATA | B18: Azucar | C18: 80 | D18: 80 | E18: 90 | F18: 100 | G18: 1000 | H18: 1.49 | I18: =(C18*H18)/G18 -> 0.1192 | J18: =D18*H18/G18 -> 0.1192 | K18: =(E18*H18)/G18 -> 0.1341 | L18: =(F18*H18)/G18 -> 0.149
B19: Vainilla | C19: 5 | D19: 5 | E19: 7 | F19: 9 | G19: 236 | H19: 6.9 | I19: =(C19*H19)/G19 -> 0.14618644 | J19: =D19*H19/G19 -> 0.14618644 | K19: =(E19*H19)/G19 -> 0.20466102 | L19: =(F19*H19)/G19 -> 0.26313559
B20: nata | C20: 100 | D20: 200 | E20: 300 | F20: 400 | G20: 600 | H20: 2.36 | I20: =(C20*H20)/G20 -> 0.39333333 | J20: =D20*H20/G20 -> 0.78666667 | K20: =(E20*H20)/G20 -> 1.18 | L20: =(F20*H20)/G20 -> 1.5733333
I21: =SUM(I16:I20) -> 2.3220531 | J21: =SUM(J16:J20) -> 4.3787198 | K21: =SUM(K16:K20) -> 6.508761 | L21: =SUM(L16:L20) -> 8.6388023
A23: COBERTURA | B23: AZUCAR | C23: 180 | D23: 180 | E23: 360 | F23: 360 | G23: 1000 | H23: 1.49 | I23: =(C23*H23)/G23 -> 0.2682 | J23: =D23*H23/G23 -> 0.2682 | K23: =(E23*H23)/G23 -> 0.5364 | L23: =(F23*H23)/G23 -> 0.5364
A24: YEMA | B24: AGUA | C24: 60 | D24: 60 | E24: 120 | F24: 120 | G24: 1000 | H24: 1 | I24: =(C24*H24)/G24 -> 0.06 | J24: =D24*H24/G24 -> 0.06 | K24: =(E24*H24)/G24 -> 0.12 | L24: =(F24*H24)/G24 -> 0.12
A25: Y NATA | B25: YEMAS | C25: 4 | D25: 4 | E25: 8 | F25: 8 | G25: 12 | H25: 2.5 | I25: =(C25*H25)/G25 -> 0.83333333 | J25: =D25*H25/G25 -> 0.83333333 | K25: =(E25*H25)/G25 -> 1.6666667 | L25: =(F25*H25)/G25 -> 1.6666667
B26: MAICENA | C26: 7 | D26: 7 | E26: 14 | F26: 14 | G26: 400 | H26: 4 | I26: =(C26*H26)/G26 -> 0.07 | J26: =D26*H26/G26 -> 0.07 | K26: =(E26*H26)/G26 -> 0.14 | L26: =(F26*H26)/G26 -> 0.14
I27: =SUM(I23:I26) -> 1.2315333 | J27: =SUM(J23:J26) -> 1.2315333 | K27: =SUM(K23:K26) -> 2.4630667 | L27: =SUM(L23:L26) -> 2.4630667
B29: papel horno | C29: 1 | D29: 1 | E29: 1 | F29: 1 | G29: 20 | H29: 1.13 | I29: =(C29*H29)/G29 -> 0.0565 | J29: =D29*H29/G29 -> 0.0565 | K29: =(C29*H29)/G29 -> 0.0565 | L29: =(F29*H29)/G29 -> 0.0565
B30: Papel plata | C30: 1 | D30: 1 | E30: 1 | F30: 1 | G30: 1000 | H30: 2.05 | I30: =(C30*H30)/G30 -> 0.00205 | J30: =D30*H30/G30 -> 0.00205 | K30: =(C30*H30)/G30 -> 0.00205 | L30: =(F30*H30)/G30 -> 0.00205
B31: Horno | C31: 30 | D31: 30 | E31: 35 | F31: 40 | G31: 60 | H31: 1 | I31: =(C31*H31)/G31 -> 0.5 | J31: =D31*H31/G31 -> 0.5 | K31: =(C31*H31)/G31 -> 0.5 | L31: =(F31*H31)/G31 -> 0.66666667
A32: COSTES | B32: Agua | C32: 12 | D32: 12 | E32: 12 | F32: 12 | G32: 1000 | H32: 1.97 | I32: =(C32*H32)/G32 -> 0.02364 | J32: =D32*H32/G32 -> 0.02364 | K32: =(C32*H32)/G32 -> 0.02364 | L32: =(F32*H32)/G32 -> 0.02364
A33: INDIRECTOS | B33: Batidora | C33: 12 | D33: 12 | E33: 12 | F33: 12 | G33: 60 | H33: 1 | I33: =(C33*H33)/G33 -> 0.2 | J33: =D33*H33/G33 -> 0.2 | K33: =(C33*H33)/G33 -> 0.2 | L33: =(F33*H33)/G33 -> 0.2
B34: CLARAS | C34: 2 | D34: 2 | E34: 2 | F34: 22 | G34: 12 | H34: 2.5 | I34: =(C34*H34)/G34 -> 0.41666667 | J34: =D34*H34/G34 -> 0.41666667 | K34: =(C34*H34)/G34 -> 0.41666667 | L34: =(F34*H34)/G34 -> 4.5833333
I37: =SUM(I29:I36) -> 1.1988567 | J37: =SUM(J29:J36) -> 1.1988567 | K37: =SUM(K29:K36) -> 1.1988567 | L37: =SUM(L29:L36) -> 5.53219
B40: Topper | C40: 1 | D40: 1 | E40: 1 | F40: 1 | G40: 1 | H40: 1.8 | I40: =(C40*H40)/G40 -> 1.8 | J40: =D40*H40/G40 -> 1.8 | K40: =(C40*H40)/G40 -> 1.8 | L40: =(F40*H40)/G40 -> 1.8
B41: Vela | C41: 1 | D41: 1 | E41: 1 | F41: 1 | G41: 6 | H41: 1 | I41: =(C41*H41)/G41 -> 0.16666667 | J41: =D41*H41/G41 -> 0.16666667 | K41: =(C41*H41)/G41 -> 0.16666667 | L41: =(F41*H41)/G41 -> 0.16666667
B42: Plato 25 cm | C42: 1 | D42: 1 | E42: 1 | F42: 1 | G42: 1 | H42: 0.9 | I42: =(C42*H42)/G42 -> 0.9 | J42: =D42*H42/G42 -> 0.9 | K42: =(C42*H42)/G42 -> 0.9 | L42: =(F42*H42)/G42 -> 0.9
A43: EXTRAS | B43: Caja 25,5 | C43: 1 | D43: 1 | E43: 1 | F43: 1 | G43: 1 | H43: 2 | I43: =(C43*H43)/G43 -> 2 | J43: =D43*H43/G43 -> 2 | K43: =(C43*H43)/G43 -> 2 | L43: =(F43*H43)/G43 -> 2
B44: Etiqueta | C44: 1 | D44: 1 | E44: 1 | F44: 1 | G44: 500 | H44: 0.85 | I44: =(C44*H44)/G44 -> 0.0017 | J44: =D44*H44/G44 -> 0.0017 | K44: =(C44*H44)/G44 -> 0.0017 | L44: =(F44*H44)/G44 -> 0.0017
B45: Banda | C45: 2 | D45: 2 | E45: 2 | F45: 2 | G45: 2 | H45: 0.18 | I45: =(C45*H45)/G45 -> 0.18 | J45: =D45*H45/G45 -> 0.18 | K45: =(C45*H45)/G45 -> 0.18 | L45: =(F45*H45)/G45 -> 0.18
B46: Sprinkles | C46: 10 | D46: 10 | E46: 10 | F46: 10 | G46: 100 | H46: 6 | I46: =(C46*H46)/G46 -> 0.6 | J46: =D46*H46/G46 -> 0.6 | K46: =(C46*H46)/G46 -> 0.6 | L46: =(F46*H46)/G46 -> 0.6
B47: Decoraciones | C47: 3 | D47: 3 | E47: 3 | F47: 3 | G47: 10 | H47: 1 | I47: =(C47*H47)/G47 -> 0.3 | J47: =D47*H47/G47 -> 0.3 | K47: =(C47*H47)/G47 -> 0.3 | L47: =(F47*H47)/G47 -> 0.3
I48: =SUM(I40:I47) -> 5.9483667 | J48: =SUM(J40:J47) -> 5.9483667 | K48: =SUM(K40:K47) -> 5.9483667 | L48: =SUM(L40:L47) -> 5.9483667
H50: COSTE PROD | I50: =SUM(I9+I14+I21+I27+I37+I48) -> 12.534375 | J50: =SUM(J9+J14+J21+J27+J37+J48) -> 15.186171 | K50: =SUM(K9+K14+K21+K27+K37+K48) -> 19.099677 | L50: =SUM(L9+L14+L21+L27+L37+L48) -> 26.198321
H51: PVP | I51: 30 | J51: 35 | K51: 40 | L51: 45
H52: GANANCIA | I52: =I51-I50 -> 17.465625 | J52: =J51-J50 -> 19.813829 | K52: =K51-K50 -> 20.900323 | L52: =L51-L50 -> 18.801679

Sheet TARTA OREO
C3: 8-10P | D3: 12-15 P | E3: 20 P | F3: 25P
B4: INGREDIENTES | C4: 16 CM | D4: 18,5 CM | E4: 20 CM | F4: 24 CM | G4: UNIDADES PAQ | H4: PRECIO | I4: COSTO 16 | J4: COSTO 18 | K4: COSTO 20 | L4: COSTO 24
B5: Harina | C5: 140 | D5: 170 | E5: 230 | F5: 260 | G5: 1000 | H5: 1.07 | I5: =(C5*H5)/G5 -> 0.1498 | J5: =D6*H6/G6 -> 1.25 | K5: =(E5*H5)/G5 -> 0.2461 | L5: =(F5*H5)/G5 -> 0.2782
A6: BiZCOCHO | B6: Huevos | C6: 5 | D6: 6 | E6: 8 | F6: 9 | G6: 12 | H6: 2.5 | I6: =(C6*H6)/G6 -> 1.0416667 | J6: =D7*H7/G7 -> 0.225 | K6: =(E6*H6)/G6 -> 1.6666667 | L6: =(F6*H6)/G6 -> 1.875
A7: CHOCOLATE | B7: Azucar | C7: 150 | D7: 180 | E7: 240 | F7: 270 | G7: 1000 | H7: 1.25 | I7: =(C7*H7)/G7 -> 0.1875 | J7: =D8*H8/G8 -> 0.29237288 | K7: =(E7*H7)/G7 -> 0.3 | L7: =(F7*H7)/G7 -> 0.3375
B8: Vainilla | C8: 5 | D8: 10 | E8: 10 | F8: 10 | G8: 236 | H8: 6.9 | I8: =(C8*H8)/G8 -> 0.14618644 | J8: =D9*H9/G9 -> 0.22727273 | K8: =(E8*H8)/G8 -> 0.29237288 | L8: =(F8*H8)/G8 -> 0.29237288
B9: GALLETA OREO | C9: 40 | D9: 50 | E9: 60 | F9: 70 | G9: 220 | H9: 1 | I9: =(C9*H9)/G9 -> 0.18181818 | J9: =D10*H10/G10 -> 0.72 | K9: =(E9*H9)/G9 -> 0.27272727 | L9: =(F9*H9)/G9 -> 0.31818182
B10: Cacao | C10: 30 | D10: 30 | E10: 40 | F10: 50 | G10: 250 | H10: 6 | I10: =(C10*H10)/G10 -> 0.72 | J10: =D11*H11/G11 -> 0.07475 | K10: =(E10*H10)/G10 -> 0.96 | L10: =(F10*H10)/G10 -> 1.2
B11: Maicena | C11: 20 | D11: 10 | E11: 10 | F11: 10 | G11: 400 | H11: 2.99 | I11: =(C11*H11)/G11 -> 0.1495 | J11: =D11*H11/G11 -> 0.07475 | K11: =(E11*H11)/G11 -> 0.07475 | L11: =(F11*H11)/G11 -> 0.07475
I12: =SUM(I5:I11) -> 2.5764713 | J12: =SUM(J5:J11) -> 2.8641456 | K12: =SUM(K5:K11) -> 3.8126168 | L12: =SUM(L5:L11) -> 4.3760047
B14: Azucar | C14: 100 | D14: 120 | E14: 150 | F14: 200 | G14: 1000 | H14: 1.25 | I14: =(C14*H14)/G14 -> 0.125 | J14: =D14*H14/G14 -> 0.15 | K14: =(E14*H14)/G14 -> 0.1875 | L14: =(F14*H14)/G14 -> 0.25
A15: ALMIBAR | B15: Agua | C15: 100 | D15: 120 | E15: 150 | F15: 200 | G15: 1000 | H15: 0.25 | I15: =(C15*H15)/G15 -> 0.025 | J15: =D15*H15/G15 -> 0.03 | K15: =(E15*H15)/G15 -> 0.0375 | L15: =(F15*H15)/G15 -> 0.05
B16: Vainilla | C16: 3 | D16: 4 | E16: 5 | F16: 9 | G16: 236 | H16: 6.9 | I16: =(C16*H16)/G16 -> 0.087711864 | J16: =D16*H16/G16 -> 0.11694915 | K16: =(E16*H16)/G16 -> 0.14618644 | L16: =(F16*H16)/G16 -> 0.26313559
I17: =SUM(I14:I16) -> 0.23771186 | J17: =SUM(J14:J16) -> 0.29694915 | K17: =SUM(K14:K16) -> 0.37118644 | L17: =SUM(L14:L16) -> 0.56313559
B19: Nata | C19: 300 | D19: 400 | E19: 500 | F19: 600 | G19: 600 | H19: 2.36 | I19: =(C19*H19)/G19 -> 1.18 | J19: =(D19*H19)/G19 -> 1.5733333 | K19: =(E19*H19)/G19 -> 1.9666667 | L19: =(F19*H19)/G19 -> 2.36
A20: RELLENO | B20: Queso phila | C20: 100 | D20: 150 | E20: 200 | F20: 200 | G20: 250 | H20: 2 | I20: =(C20*H20)/G20 -> 0.8 | J20: =(D20*H20)/G20 -> 1.2 | K20: =(E20*H20)/G20 -> 1.6 | L20: =(F20*H20)/G20 -> 1.6
A21: OREO | B21: OREO GALLETA | C21: 100 | D21: 120 | E21: 140 | F21: 150 | G21: 220 | H21: 1 | I21: =(C21*H21)/G21 -> 0.45454545 | J21: =(D21*H21)/G21 -> 0.54545455 | K21: =(E21*H21)/G21 -> 0.63636364 | L21: =(F21*H21)/G21 -> 0.68181818
B22: Azucar blanca | C22: 80 | D22: 90 | E22: 100 | F22: 120 | G22: 1000 | H22: 1.49 | I22: =(C22*H22)/G22 -> 0.1192 | J22: =(D22*H22)/G22 -> 0.1341 | K22: =(E22*H22)/G22 -> 0.149 | L22: =(F22*H22)/G22 -> 0.1788
B23: Vainilla | C23: 5 | D23: 7 | E23: 9 | F23: 8 | G23: 236 | H23: 6.9 | I23: =(C23*H23)/G23 -> 0.14618644 | J23: =(D23*H23)/G23 -> 0.20466102 | K23: =(E23*H23)/G23 -> 0.26313559 | L23: =(F23*H23)/G23 -> 0.23389831
I24: =SUM(I19:I23) -> 2.6999319 | J24: =SUM(J19:J23) -> 3.6575489 | K24: =SUM(K19:K23) -> 4.6151659 | L24: =SUM(L19:L23) -> 5.0545165
A26: COBERTURA | B26: Nata | C26: 150 | D26: 200 | E26: 200 | F26: 450 | G26: 600 | H26: 2.36 | I26: =(C26*H26)/G26 -> 0.59 | J26: =(D26*H26)/G26 -> 0.78666667 | K26: =(E26*H26)/G26 -> 0.78666667 | L26: =(F26*H26)/G26 -> 1.77
A27: CREMA DE | B27: CHOCOLATE | C27: 500 | D27: 600 | E27: 600 | F27: 900 | G27: 100 | H27: 1.15 | I27: =(C27*H27)/G27 -> 5.75 | J27: =(D27*H27)/G27 -> 6.9 | K27: =(E27*H27)/G27 -> 6.9 | L27: =(F27*H27)/G27 -> 10.35
A28: GANACHE | B28: OREO DECORAR | C28: 50 | D28: 70 | E28: 90 | F28: 100 | G28: 100 | H28: 0.79 | I28: =(C28*H28)/G28 -> 0.395 | J28: =(D28*H28)/G28 -> 0.553 | K28: =(E28*H28)/G28 -> 0.711 | L28: =(F28*H28)/G28 -> 0.79
B29: OREO DECORAR | C29: 50 | D29: 70 | E29: 90 | F29: 100 | G29: 220 | H29: 1 | I29: =(C29*H29)/G29 -> 0.22727273 | J29: =(D29*H29)/G29 -> 0.31818182 | K29: =(E29*H29)/G29 -> 0.40909091 | L29: =(F29*H29)/G29 -> 0.45454545
I30: =SUM(I26:I29) -> 6.9622727 | J30: =SUM(J26:J29) -> 8.5578485 | K30: =SUM(K26:K29) -> 8.8067576 | L30: =SUM(L26:L29) -> 13.364545
B32: papel horno | C32: 1 | D32: 1 | E32: 1 | F32: 1 | G32: 20 | H32: 1.13 | I32: =(C32*H32)/G32 -> 0.0565 | J32: =D32*H32/G32 -> 0.0565 | K32: =(C32*H32)/G32 -> 0.0565 | L32: =(F32*H32)/G32 -> 0.0565
B33: Papel plata | C33: 1 | D33: 1 | E33: 1 | F33: 1 | G33: 1000 | H33: 2.05 | I33: =(C33*H33)/G33 -> 0.00205 | J33: =D33*H33/G33 -> 0.00205 | K33: =(C33*H33)/G33 -> 0.00205 | L33: =(F33*H33)/G33 -> 0.00205
B34: Horno | C34: 30 | D34: 30 | E34: 35 | F34: 40 | G34: 60 | H34: 1 | I34: =(C34*H34)/G34 -> 0.5 | J34: =D34*H34/G34 -> 0.5 | K34: =(C34*H34)/G34 -> 0.5 | L34: =(F34*H34)/G34 -> 0.66666667
A35: COSTES | B35: Agua | C35: 12 | D35: 12 | E35: 12 | F35: 12 | G35: 1000 | H35: 1.97 | I35: =(C35*H35)/G35 -> 0.02364 | J35: =D35*H35/G35 -> 0.02364 | K35: =(C35*H35)/G35 -> 0.02364 | L35: =(F35*H35)/G35 -> 0.02364
A36: INDIRECTOS | B36: Batidora | C36: 12 | D36: 12 | E36: 12 | F36: 12 | G36: 60 | H36: 1 | I36: =(C36*H36)/G36 -> 0.2 | J36: =D36*H36/G36 -> 0.2 | K36: =(C36*H36)/G36 -> 0.2 | L36: =(F36*H36)/G36 -> 0.2
I40: =SUM(I32:I39) -> 0.78219 | J40: =SUM(J32:J39) -> 0.78219 | K40: =SUM(K32:K39) -> 0.78219 | L40: =SUM(L32:L39) -> 0.94885667
B43: Topper | C43: 1 | D43: 1 | E43: 1 | F43: 1 | G43: 1 | H43: 1.8 | I43: =(C43*H43)/G43 -> 1.8 | J43: =(C43*H43)/G43 -> 1.8 | K43: =(E43*H43)/G43 -> 1.8 | L43: =(F43*H43)/G43 -> 1.8
B44: Vela | C44: 1 | D44: 1 | E44: 1 | F44: 1 | G44: 6 | H44: 1 | I44: =(C44*H44)/G44 -> 0.16666667 | J44: =(C44*H44)/G44 -> 0.16666667 | K44: =(E44*H44)/G44 -> 0.16666667 | L44: =(F44*H44)/G44 -> 0.16666667
B45: Plato 25 cm | C45: 1 | D45: 1 | E45: 1 | F45: 0 | G45: 1 | H45: 0.9 | I45: =(C45*H45)/G45 -> 0.9 | J45: =(C45*H45)/G45 -> 0.9 | K45: =(E45*H45)/G45 -> 0.9 | L45: =(F45*H45)/G45 -> 0
A46: EXTRAS | B46: Caja 25,5 | C46: 1 | D46: 1 | E46: 1 | F46: 0 | G46: 1 | H46: 2 | I46: =(C46*H46)/G46 -> 2 | J46: =(C46*H46)/G46 -> 2 | K46: =(E46*H46)/G46 -> 2 | L46: =(F46*H46)/G46 -> 0
B47: Etiqueta | C47: 1 | D47: 1 | E47: 1 | F47: 1 | G47: 500 | H47: 0.85 | I47: =(C47*H47)/G47 -> 0.0017 | J47: =(C47*H47)/G47 -> 0.0017 | K47: =(E47*H47)/G47 -> 0.0017 | L47: =(F47*H47)/G47 -> 0.0017
B48: Banda | C48: 2 | D48: 2 | E48: 2 | F48: 1 | G48: 2 | H48: 0.18 | I48: =(C48*H48)/G48 -> 0.18 | J48: =(C48*H48)/G48 -> 0.18 | K48: =(E48*H48)/G48 -> 0.18 | L48: =(F48*H48)/G48 -> 0.09
B49: plato 28 cm | C49: 0 | D49: 0 | E49: 0 | F49: 1 | G49: 1 | H49: 0.9 | I49: =(C49*H49)/G49 -> 0 | J49: =(C49*H49)/G49 -> 0 | K49: =(E49*H49)/G49 -> 0 | L49: =(F49*H49)/G49 -> 0.9
B50: caja 28 cm | C50: 0 | D50: 0 | E50: 0 | F50: 1 | G50: 1 | H50: 2 | I50: =(C50*H50)/G50 -> 0 | J50: =(C50*H50)/G50 -> 0 | K50: =(E50*H50)/G50 -> 0 | L50: =(F50*H50)/G50 -> 2
B51: Sprinkles | C51: 10 | D51: 10 | E51: 10 | F51: 12 | G51: 100 | H51: 6 | I51: =(C51*H51)/G51 -> 0.6 | J51: =(C51*H51)/G51 -> 0.6 | K51: =(E51*H51)/G51 -> 0.6 | L51: =(F51*H51)/G51 -> 0.72
...

Sheet CHEESECAKE
C2: FRUTOS ROJOS
A3: INGREDIENTES | B3: 16 CM | C3: 18 CM | D3: 20CM | E3: 24 CM | F3: PRECIO | G3: UN PAQUETE | H3: COSTE 16 CM | I3: COSTE 18 CM | J3: COSTE 20 CM | K3: COSTE 24 CM
A4: GALLETA RELIEVE | B4: 125 | C4: 175 | D4: 245 | E4: 345 | F4: 1.65 | G4: 735 | H4: =B4*F4/G4 -> 0.28061224 | I4: =C4*F4/G4 -> 0.39285714 | J4: =D4*F4/G4 -> 0.55 | K4: =E4*F4/G4 -> 0.7744898
A5: MANTEQUILLA | B5: 100 | C5: 150 | D5: 200 | E5: 300 | F5: 2.39 | G5: 250 | H5: =B5*F5/G5 -> 0.956 | I5: =C5*F5/G5 -> 1.434 | J5: =D5*F5/G5 -> 1.912 | K5: =E5*F5/G5 -> 2.868
A6: QUESO MASCARPONE | B6: 150 | C6: 200 | D6: 250 | E6: 300 | F6: 2.65 | G6: 250 | H6: =B6*F6/G6 -> 1.59 | I6: =C6*F6/G6 -> 2.12 | J6: =D6*F6/G6 -> 2.65 | K6: =E6*F6/G6 -> 3.18
A7: QUESO PHILA | B7: 150 | C7: 200 | D7: 250 | E7: 300 | F7: 2.78 | G7: 250 | H7: =B7*F7/G7 -> 1.668 | I7: =C7*F7/G7 -> 2.224 | J7: =D7*F7/G7 -> 2.78 | K7: =E7*F7/G7 -> 3.336
A8: NATA | B8: 100 | C8: 150 | D8: 200 | E8: 300 | F8: 2.39 | G8: 600 | H8: =B8*F8/G8 -> 0.39833333 | I8: =C8*F8/G8 -> 0.5975 | J8: =D8*F8/G8 -> 0.79666667 | K8: =E8*F8/G8 -> 1.195
A9: LIMON | B9: 1 | C9: 1 | D9: 1 | E9: 1 | F9: 0.59 | G9: 1 | H9: =B9*F9/G9 -> 0.59 | I9: =C9*F9/G9 -> 0.59 | J9: =D9*F9/G9 -> 0.59 | K9: =E9*F9/G9 -> 0.59
A10: VAINILLA | B10: 5 | C10: 5 | D10: 4 | E10: 4 | F10: 6.9 | G10: 236 | H10: =B10*F10/G10 -> 0.14618644 | I10: =C10*F10/G10 -> 0.14618644 | J10: =D10*F10/G10 -> 0.11694915 | K10: =E10*F10/G10 -> 0.11694915
A11: FRUTOS ROJOS | B11: 300 | C11: 300 | D11: 300 | E11: 350 | F11: 1.68 | G11: 300 | H11: =B11*F11/G11 -> 1.68 | I11: =C11*F11/G11 -> 1.68 | J11: =D11*F11/G11 -> 1.68 | K11: =E11*F11/G11 -> 1.96
H12: =SUM(H4:H11) -> 7.309132 | I12: =SUM(I4:I11) -> 9.1845436 | J12: =SUM(J4:J11) -> 11.075616 | K12: =SUM(K4:K11) -> 14.020439
A14: PAPEL PLATA | B14: 0.6 | C14: 0.6 | D14: 0.6 | E14: 0.6 | F14: 2.35 | G14: 30 | H14: =B14*F14/G14 -> 0.047 | I14: =C14*F14/G14 -> 0.047 | J14: =D14*F14/G14 -> 0.047 | K14: =E14*F14/G14 -> 0.047
A15: HORNO | B15: 1 | C15: 1 | D15: 1 | E15: 1 | F15: 1.13 | G15: 20 | H15: =B15*F15/G15 -> 0.0565 | I15: =C15*F15/G15 -> 0.0565 | J15: =D15*F15/G15 -> 0.0565 | K15: =E15*F15/G15 -> 0.0565
A16: NEVERA | B16: 1 | C16: 1 | D16: 1 | E16: 1 | F16: 1.13 | G16: 20 | H16: =B16*F16/G16 -> 0.0565 | I16: =C16*F16/G16 -> 0.0565 | J16: =D16*F16/G16 -> 0.0565 | K16: =E16*F16/G16 -> 0.0565
A17: TOPPER | B17: 1 | C17: 1 | D17: 1 | E17: 1 | F17: 0.75 | G17: 1 | H17: =B17*F17/G17 -> 0.75 | I17: =C17*F17/G17 -> 0.75 | J17: =D17*F17/G17 -> 0.75 | K17: =E17*F17/G17 -> 0.75
A18: VELA | B18: 1 | C18: 1 | D18: 1 | E18: 1 | F18: 1 | G18: 20 | H18: =B18*F18/G18 -> 0.05 | I18: =C18*F18/G18 -> 0.05 | J18: =D18*F18/G18 -> 0.05 | K18: =E18*F18/G18 -> 0.05
A19: PLATO 20 CM | B19: 1 | D19: 1 | F19: 0.75 | G19: 1 | H19: =B19*F19/G19 -> 0.75 | I19: =C19*F19/G19 -> 0 | J19: =D19*F19/G19 -> 0.75 | K19: =E19*F19/G19 -> 0
A20: PLATO 25-24 CM | C20: 1 | D20: 1 | E20: 1 | F20: 0.85 | G20: 1 | H20: =B20*F20/G20 -> 0 | I20: =C20*F20/G20 -> 0.85 | J20: =D20*F20/G20 -> 0.85 | K20: =E20*F20/G20 -> 0.85
A21: CAJA 20 CM | B21: 1 | D21: 1 | F21: 1.95 | G21: 1 | H21: =B21*F21/G21 -> 1.95 | I21: =C21*F21/G21 -> 0 | J21: =D21*F21/G21 -> 1.95 | K21: =E21*F21/G21 -> 0
A22: CAJA 25X25 | C22: 1 | D22: 1 | E22: 1 | F22: 2.2 | G22: 1 | H22: =B22*F22/G22 -> 0 | I22: =C22*F22/G22 -> 2.2 | J22: =D22*F22/G22 -> 2.2 | K22: =E22*F22/G22 -> 2.2
H23: =SUM( H14:H22) -> 3.66 | I23: =SUM(I14:I22) -> 4.01 | J23: =SUM(J14:J22) -> 6.71 | K23: =SUM(K14:K22) -> 4.01
G26: COSTE TOTAL | H26: =SUM(H12+H23) -> 10.969132 | I26: =SUM(I12+I23) -> 13.194544 | J26: =SUM(J12+J23) -> 17.785616 | K26: =SUM(K12+K23) -> 18.030439
G27: PRECIO VENTA | H27: 18 | I27: 22 | J27: 28 | K27: 30
G28: GANANCIA | H28: =H27-H26 -> 7.030868 | I28: =I27-I26 -> 8.8054564 | J28: =J27-J26 -> 10.214384 | K28: =K27-K26 -> 11.969561
C32: DULCE DE LECHE O LOTUS
A33: INGREDIENTES | B33: 16 CM | C33: 18 CM | D33: 20CM | E33: 24 CM | F33: PRECIO | G33: UN PAQUETE | H33: COSTE 16 CM | I33: COSTE 18 CM | J33: COSTE 20 CM | K33: COSTE 24 CM
A34: GALLETA RELIEVE | B34: 125 | C34: 175 | D34: 245 | E34: 345 | F34: 1.65 | G34: 735 | H34: =B34*F34/G34 -> 0.28061224 | I34: =C34*F34/G34 -> 0.39285714 | J34: =D34*F34/G34 -> 0.55 | K34: =E34*F34/G34 -> 0.7744898
A35: MANTEQUILLA | B35: 100 | C35: 150 | D35: 200 | E35: 300 | F35: 2.39 | G35: 250 | H35: =B35*F35/G35 -> 0.956 | I35: =C35*F35/G35 -> 1.434 | J35: =D35*F35/G35 -> 1.912 | K35: =E35*F35/G35 -> 2.868
A36: QUESO MASCARPONE | B36: 100 | C36: 150 | D36: 200 | E36: 250 | F36: 2.65 | G36: 250 | H36: =B36*F36/G36 -> 1.06 | I36: =C36*F36/G36 -> 1.59 | J36: =D36*F36/G36 -> 2.12 | K36: =E36*F36/G36 -> 2.65
A37: DULCE DE LECHE | B37: 100 | C37: 150 | D37: 200 | E37: 250 | F37: 5 | G37: 1000 | H37: =B37*F37/G37 -> 0.5 | I37: =C37*F37/G37 -> 0.75 | J37: =D37*F37/G37 -> 1 | K37: =E37*F37/G37 -> 1.25
A38: QUESO PHILA | B38: 100 | C38: 150 | D38: 200 | E38: 250 | F38: 2.78 | G38: 250 | H38: =B38*F38/G38 -> 1.112 | I38: =C38*F38/G38 -> 1.668 | J38: =D38*F38/G38 -> 2.224 | K38: =E38*F38/G38 -> 2.78
A39: NATA | B39: 100 | C39: 150 | D39: 200 | E39: 300 | F39: 2.39 | G39: 600 | H39: =B39*F39/G39 -> 0.39833333 | I39: =C39*F39/G39 -> 0.5975 | J39: =D39*F39/G39 -> 0.79666667 | K39: =E39*F39/G39 -> 1.195
A40: LIMON | B40: 1 | C40: 1 | D40: 1 | E40: 1 | F40: 0.59 | G40: 1 | H40: =B40*F40/G40 -> 0.59 | I40: =C40*F40/G40 -> 0.59 | J40: =D40*F40/G40 -> 0.59 | K40: =E40*F40/G40 -> 0.59
A41: VAINILLA | B41: 5 | C41: 5 | D41: 4 | E41: 4 | F41: 6.9 | G41: 236 | H41: =B41*F41/G41 -> 0.14618644 | I41: =C41*F41/G41 -> 0.14618644 | J41: =D41*F41/G41 -> 0.11694915 | K41: =E41*F41/G41 -> 0.11694915
A42: DDL DECORACION | B42: 100 | C42: 150 | D42: 200 | E42: 250 | F42: 5 | G42: 1000 | H42: =B42*F42/G42 -> 0.5 | I42: =C42*F42/G42 -> 0.75 | J42: =D42*F42/G42 -> 1 | K42: =E42*F42/G42 -> 1.25
H43: =SUM(H34:H42) -> 5.543132 | I43: =SUM(I34:I42) -> 7.9185436 | J43: =SUM(J34:J42) -> 10.309616 | K43: =SUM(K34:K42) -> 13.474439
A44: PAPEL PLATA | B44: 0.6 | C44: 0.6 | D44: 0.6 | E44: 0.6 | F44: 2.35 | G44: 30 | H44: =B44*F44/G44 -> 0.047 | I44: =C44*F44/G44 -> 0.047 | J44: =D44*F44/G44 -> 0.047 | K44: =E44*F44/G44 -> 0.047
A45: HORNO | B45: 1 | C45: 1 | D45: 1 | E45: 1 | F45: 1.13 | G45: 20 | H45: =B45*F45/G45 -> 0.0565 | I45: =C45*F45/G45 -> 0.0565 | J45: =D45*F45/G45 -> 0.0565 | K45: =E45*F45/G45 -> 0.0565
A46: NEVERA | B46: 1 | C46: 1 | D46: 1 | E46: 1 | F46: 1.13 | G46: 20 | H46: =B46*F46/G46 -> 0.0565 | I46: =C46*F46/G46 -> 0.0565 | J46: =D46*F46/G46 -> 0.0565 | K46: =E46*F46/G46 -> 0.0565
A47: TOPPER | B47: 1 | C47: 1 | D47: 1 | E47: 1 | F47: 0.75 | G47: 1 | H47: =B47*F47/G47 -> 0.75 | I47: =C47*F47/G47 -> 0.75 | J47: =D47*F47/G47 -> 0.75 | K47: =E47*F47/G47 -> 0.75
...

Sheet TARTA FRESAS CON NATA
A1: TARTA FRESAS CON NATA
B3: INGREDIENTES | C3: CANT 8-10 p | D3: CANT 12-15 | E3: CANT 18-20 p | F3: CANT 25-28 | G3: UNIDADES PAQ | H3: PRECIO | I3: COSTO 8-10 p | J3: COSTO 12-15 | K3: COSTO 18-20 p | L3: COSTO 25-28
A5: BIZCOCHO | B5: Harina | C5: 150 | D5: 180 | E5: 240 | F5: 270 | G5: 1000 | H5: 1.07 | I5: =(C5*H5)/G5 -> 0.1605 | J5: =D6*H6/G6 -> 1.25 | K5: =(E5*H5)/G5 -> 0.2568 | L5: =(F5*H5)/G5 -> 0.2889
A6: VAINILLA | B6: Huevos | C6: 5 | D6: 6 | E6: 8 | F6: 9 | G6: 12 | H6: 2.5 | I6: =(C6*H6)/G6 -> 1.0416667 | J6: =D7*H7/G7 -> 0.225 | K6: =(E6*H6)/G6 -> 1.6666667 | L6: =(F6*H6)/G6 -> 1.875
B7: Azucar | C7: 150 | D7: 180 | E7: 240 | F7: 270 | G7: 1000 | H7: 1.25 | I7: =(C7*H7)/G7 -> 0.1875 | J7: =D8*H8/G8 -> 0.29237288 | K7: =(E7*H7)/G7 -> 0.3 | L7: =(F7*H7)/G7 -> 0.3375
B8: Vainilla | C8: 5 | D8: 10 | E8: 10 | F8: 15 | G8: 236 | H8: 6.9 | I8: =(C8*H8)/G8 -> 0.14618644 | J8: =D8*H8/G8 -> 0.29237288 | K8: =(E8*H8)/G8 -> 0.29237288 | L8: =(F8*H8)/G8 -> 0.43855932
I9: =SUM(I5:I8) -> 1.5358531 | J9: =SUM(J5:J8) -> 2.0597458 | K9: =SUM(K5:K8) -> 2.5158395 | L9: =SUM(L5:L8) -> 2.9399593
B11: Azucar | C11: 100 | D11: 120 | E11: 150 | F11: 200 | G11: 1000 | H11: 1.25 | I11: =(C11*H11)/G11 -> 0.125 | J11: =D11*H11/G11 -> 0.15 | K11: =(E11*H11)/G11 -> 0.1875 | L11: =(F11*H11)/G11 -> 0.25
A12: ALMIBAR | B12: Agua | C12: 100 | D12: 120 | E12: 150 | F12: 200 | G12: 1000 | H12: 0.25 | I12: =(C12*H12)/G12 -> 0.025 | J12: =D12*H12/G12 -> 0.03 | K12: =(E12*H12)/G12 -> 0.0375 | L12: =(F12*H12)/G12 -> 0.05
B13: Vainilla | C13: 3 | D13: 4 | E13: 5 | F13: 9 | G13: 236 | H13: 6.9 | I13: =(C13*H13)/G13 -> 0.087711864 | J13: =D13*H13/G13 -> 0.11694915 | K13: =(E13*H13)/G13 -> 0.14618644 | L13: =(F13*H13)/G13 -> 0.26313559
I14: =SUM(I11:I13) -> 0.23771186 | J14: =SUM(J11:J13) -> 0.29694915 | K14: =SUM(K11:K13) -> 0.37118644 | L14: =SUM(L11:L13) -> 0.56313559
A15: RELLENO | B15: QUESO | C15: 150 | D15: 200 | E15: 200 | F15: 250 | G15: 1000 | H15: 3.85 | I15: =(C15*H15)/G15 -> 0.5775 | J15: =D15*H15/G15 -> 0.77 | K15: =(E15*H15)/G15 -> 0.77 | L15: =(F15*H15)/G15 -> 0.9625
A16: D.D.L Y | B16: Nata | C16: 300 | D16: 300 | E16: 600 | F16: 700 | G16: 600 | H16: 2.19 | I16: =(C16*H16)/G16 -> 1.095 | J16: =D16*H16/G16 -> 1.095 | K16: =(E16*H16)/G16 -> 2.19 | L16: =(F16*H16)/G16 -> 2.555
A17: NATA + melocoton | B17: Azucar | C17: 80 | D17: 80 | E17: 90 | F17: 100 | G17: 1000 | H17: 1.25 | I17: =(C17*H17)/G17 -> 0.1 | J17: =D17*H17/G17 -> 0.1 | K17: =(E17*H17)/G17 -> 0.1125 | L17: =(F17*H17)/G17 -> 0.125
B18: Vainilla | C18: 5 | D18: 5 | E18: 7 | F18: 9 | G18: 236 | H18: 6.9 | I18: =(C18*H18)/G18 -> 0.14618644 | J18: =D18*H18/G18 -> 0.14618644 | K18: =(E18*H18)/G18 -> 0.20466102 | L18: =(F18*H18)/G18 -> 0.26313559
B19: FRESAS | C19: 100 | D19: 120 | E19: 150 | F19: 200 | G19: 1000 | H19: 5 | I19: =(C19*H19)/G19 -> 0.5 | J19: =D19*H19/G19 -> 0.6 | K19: =(E19*H19)/G19 -> 0.75 | L19: =(F19*H19)/G19 -> 1
I20: =SUM(I15:I19) -> 2.4186864 | J20: =SUM(J15:J19) -> 2.7111864 | K20: =SUM(K15:K19) -> 4.027161 | L20: =SUM(L15:L19) -> 4.9056356
A22: COBERTURA | B22: Nata | C22: 300 | D22: 350 | E22: 300 | F22: 400 | G22: 600 | H22: 2.19 | I22: =(C22*H22)/G22 -> 1.095 | J22: =D22*H22/G22 -> 1.2775 | K22: =(E22*H22)/G22 -> 1.095 | L22: =(F22*H22)/G22 -> 1.46
A23: CREMA DE | B23: Queso phila | C23: 100 | D23: 120 | E23: 200 | F23: 250 | G23: 250 | H23: 1.1 | I23: =(C23*H23)/G23 -> 0.44 | J23: =D23*H23/G23 -> 0.528 | K23: =(E23*H23)/G23 -> 0.88 | L23: =(F23*H23)/G23 -> 1.1
A24: QUESO | B24: Azucar glass | C24: 50 | D24: 60 | E24: 70 | F24: 90 | G24: 1000 | H24: 4.5 | I24: =(C24*H24)/G24 -> 0.225 | J24: =D24*H24/G24 -> 0.27 | K24: =(E24*H24)/G24 -> 0.315 | L24: =(F24*H24)/G24 -> 0.405
B25: Vainilla | C25: 5 | D25: 5 | E25: 7 | F25: 9 | G25: 236 | H25: 6.9 | I25: =(C25*H25)/G25 -> 0.14618644 | J25: =D25*H25/G25 -> 0.14618644 | K25: =(E25*H25)/G25 -> 0.20466102 | L25: =(F25*H25)/G25 -> 0.26313559
I26: =SUM(I22:I25) -> 1.9061864 | J26: =SUM(J22:J25) -> 2.2216864 | K26: =SUM(K22:K25) -> 2.494661 | L26: =SUM(L22:L25) -> 3.2281356
B28: papel horno | C28: 1 | D28: 1 | E28: 1 | F28: 1 | G28: 20 | H28: 1.13 | I28: =(C28*H28)/G28 -> 0.0565 | J28: =D28*H28/G28 -> 0.0565 | K28: =(C28*H28)/G28 -> 0.0565 | L28: =(F28*H28)/G28 -> 0.0565
B29: Papel plata | C29: 1 | D29: 1 | E29: 1 | F29: 1 | G29: 1000 | H29: 2.05 | I29: =(C29*H29)/G29 -> 0.00205 | J29: =D29*H29/G29 -> 0.00205 | K29: =(C29*H29)/G29 -> 0.00205 | L29: =(F29*H29)/G29 -> 0.00205
B30: Horno | C30: 30 | D30: 30 | E30: 35 | F30: 40 | G30: 60 | H30: 1 | I30: =(C30*H30)/G30 -> 0.5 | J30: =D30*H30/G30 -> 0.5 | K30: =(C30*H30)/G30 -> 0.5 | L30: =(F30*H30)/G30 -> 0.66666667
A31: COSTES | B31: Agua | C31: 12 | D31: 12 | E31: 12 | F31: 12 | G31: 1000 | H31: 1.97 | I31: =(C31*H31)/G31 -> 0.02364 | J31: =D31*H31/G31 -> 0.02364 | K31: =(C31*H31)/G31 -> 0.02364 | L31: =(F31*H31)/G31 -> 0.02364
A32: INDIRECTOS | B32: Batidora | C32: 12 | D32: 12 | E32: 12 | F32: 12 | G32: 60 | H32: 1 | I32: =(C32*H32)/G32 -> 0.2 | J32: =D32*H32/G32 -> 0.2 | K32: =(C32*H32)/G32 -> 0.2 | L32: =(F32*H32)/G32 -> 0.2
I36: =SUM(I28:I35) -> 0.78219 | J36: =SUM(J28:J35) -> 0.78219 | K36: =SUM(K28:K35) -> 0.78219 | L36: =SUM(L28:L35) -> 0.94885667
B39: Topper | C39: 1 | D39: 1 | E39: 1 | F39: 1 | G39: 1 | H39: 1.8 | I39: =(C39*H39)/G39 -> 1.8 | J39: =D39*H39/G39 -> 1.8 | K39: =(C39*H39)/G39 -> 1.8 | L39: =(F39*H39)/G39 -> 1.8
B40: Vela | C40: 1 | D40: 1 | E40: 1 | F40: 1 | G40: 6 | H40: 1 | I40: =(C40*H40)/G40 -> 0.16666667 | J40: =D40*H40/G40 -> 0.16666667 | K40: =(C40*H40)/G40 -> 0.16666667 | L40: =(F40*H40)/G40 -> 0.16666667
B41: Plato 25 cm | C41: 1 | D41: 1 | E41: 1 | F41: 1 | G41: 1 | H41: 0.9 | I41: =(C41*H41)/G41 -> 0.9 | J41: =D41*H41/G41 -> 0.9 | K41: =(C41*H41)/G41 -> 0.9 | L41: =(F41*H41)/G41 -> 0.9
A42: EXTRAS | B42: Caja 25,5 | C42: 1 | D42: 1 | E42: 1 | F42: 1 | G42: 1 | H42: 1.85 | I42: =(C42*H42)/G42 -> 1.85 | J42: =D42*H42/G42 -> 1.85 | K42: =(C42*H42)/G42 -> 1.85 | L42: =(F42*H42)/G42 -> 1.85
B43: Etiqueta | C43: 1 | D43: 1 | E43: 1 | F43: 1 | G43: 500 | H43: 0.85 | I43: =(C43*H43)/G43 -> 0.0017 | J43: =D43*H43/G43 -> 0.0017 | K43: =(C43*H43)/G43 -> 0.0017 | L43: =(F43*H43)/G43 -> 0.0017
B44: Banda | C44: 2 | D44: 2 | E44: 2 | F44: 2 | G44: 2 | H44: 0.18 | I44: =(C44*H44)/G44 -> 0.18 | J44: =D44*H44/G44 -> 0.18 | K44: =(C44*H44)/G44 -> 0.18 | L44: =(F44*H44)/G44 -> 0.18
B45: Sprinkles | C45: 10 | D45: 10 | E45: 10 | F45: 10 | G45: 100 | H45: 6 | I45: =(C45*H45)/G45 -> 0.6 | J45: =D45*H45/G45 -> 0.6 | K45: =(C45*H45)/G45 -> 0.6 | L45: =(F45*H45)/G45 -> 0.6
B46: Decoraciones | C46: 3 | D46: 3 | E46: 3 | F46: 3 | G46: 10 | H46: 1 | I46: =(C46*H46)/G46 -> 0.3 | J46: =D46*H46/G46 -> 0.3 | K46: =(C46*H46)/G46 -> 0.3 | L46: =(F46*H46)/G46 -> 0.3
I47: =SUM(I39:I46) -> 5.7983667 | J47: =SUM(J39:J46) -> 5.7983667 | K47: =SUM(K39:K46) -> 5.7983667 | L47: =SUM(L39:L46) -> 5.7983667
I50: COSTE 16 | J50: COSTE 18 | K50: COSTE 20 | L50: COSTE 24
I51: =SUM(I9+I14+I20+I26+I36+I47) -> 12.678995 | J51: =SUM(J9+J14+J20+J26+J36+J47) -> 13.870124 | K51: =SUM(K9+K14+K20+K26+K36+K47) -> 15.989405 | L51: =SUM(L9+L14+L20+L26+L36+L47) -> 18.384089
H52: PVP | I52: 30 | J52: 35 | K52: 40 | L52: 50
...

Sheet CRUMBLE COOKIES
C1: MASA GALLETAS
A2: INGREDIENTES | B2: 1 MASA | C2: MEDIA MASA | D2: UNIDADES | E2: PRECIO | F2: COSTO 1 MASA | G2: COSTO MEDIA MASA
A3: MANTEQUILLA | B3: 280 | C3: 140 | D3: 250 | E3: 2.5 | F3: =B3*E3/D3 -> 2.8 | G3: =(C3*E3/D3) -> 1.4 | I3: CANT MASA
